Workbook
Name 物料编码: [1]产品信息!$A$3:$A$5000

Sheet 利润分析表
A1: 2026年6月广西利润分析表
A2: 附件表位置：
A3: 序号 | B3: 车牌 | D3: 负责人 | E3: 项目 | F3: 挂板车牌 | G3: 车型 | H3: 车辆趟数 | I3: 吨位 | J3: 运费产值收入 | M3: 油/电费实际金额 | N3: 油/电费占收入比% | P3: 司机工资 （提成+保底） | Q3: 司机工资占收入比% | R3: 车辆费 | AF3: 管理人员工资 | AH3: 均摊费元 | AJ3: 总车辆费用 合计 | AK3: 车贷 | AL3: 毛利 | AM3: 毛利率 | AN3: 挂板租金 | AO3: 保险费 | AP3: 毛利-租金-保险费=利润
C4: 司机 | K4: 货物险 | L4: 磅差金额 | O4: 单趟电耗 | R4: 维修费 | S4: 维修费占收入比% | T4: 配件 | U4: 配件费占收入比% | V4: 前期费用 | W4: 前期费用占收入比% | X4: 车辆费用 | Y4: 车辆费用占收入比% | Z4: 轮胎 | AA4: 轮胎费占收入比% | AB4: 罚款 | AC4: 罚款占收入比% | AD4: 税点 | AE4: 税点占收入比% | AG4: 管理人员工资占比 | AI4: 均摊占比
A5: 1 | B5: 赣J01379D | C5: 沈正元 | D5: 杨发明 | E5: 广西-玉溪 | F5: 桂LD735挂 | G5: 重型半挂牵引车 | H5: =COUNTIFS(磅单!E:E,B5) -> 1 | I5: =SUMIFS(磅单!L:L,磅单!E:E,B5) -> 41.74 | J5: =SUMIFS(磅单!O:O,磅单!E:E,B5) -> 2546.14 | K5: =SUMIFS(月汇总!Y:Y,月汇总!B:B,B5) -> 15 | L5: =SUMIFS(月汇总!I:I,月汇总!B:B,B5,月汇总!C:C,F5) -> 0 | M5: =SUMIFS(月汇总!J:J,月汇总!B:B,B5,月汇总!C:C,F5) -> 1091.9085 | N5: =M5/J5 -> 0.42884857 | O5: =M5/H5 -> 1091.9085 | P5: =SUMIFS(月汇总!R:R,月汇总!B:B,B5)+SUMIFS(月汇总!S:S,月汇总!B:B,B5) -> 600 | Q5: =P5/J5 -> 0.23565083 | R5: =SUMIFS(月汇总!Q:Q,月汇总!B:B,B5) -> 12500 | S5: =R5/J5 -> 4.9093923 | T5: =SUMIFS(月汇总!N:N,月汇总!B:B,B5) -> 220.88197 | V5: =SUMIFS(月汇总!X:X,月汇总!B:B,B5) -> 0 | W5: =V5/J5 -> 0 | X5: =SUMIFS(月汇总!U:U,月汇总!B:B,B5) -> 0 | Y5: =X5/J5 -> 0 | Z5: =SUMIFS(月汇总!O:O,月汇总!B:B,B5) -> 0 | AA5: =Z5/J5 -> 0 | AB5: =SUMIFS(月汇总!T:T,月汇总!B:B,B5) -> 0 | AC5: =AB5/J5 -> 0 | AD5: =SUMIFS(月汇总!Z:Z,月汇总!B:B,B5) -> 178.2298 | AE5: =AD5/J5 -> 0.07 | AF5: =SUMIFS(月汇总!AC:AC,月汇总!B:B,B5) -> 790.16393 | AG5: =AF5/J5 -> 0.31033798 | AH5: =SUMIFS(月汇总!V:V,月汇总!B:B,B5) -> 397.39246 | AI5: =AH5/J5 -> 0.15607644 | AJ5: =M5+P5+R5+T5+V5+X5+Z5+AB5+AD5+AF5+AH5 -> 15778.577 | AK5: =SUMIFS(月汇总!AA:AA,月汇总!B:B,B5) -> 10600 | AL5: =J5-K5-L5-AJ5-AK5 -> -23847.437 | AM5: =AL5/J5 -> -9.3661137 | AN5: =SUMIFS(月汇总!AB:AB,月汇总!B:B,B5) -> 3800 | AO5: =SUMIFS(月汇总!W:W,月汇总!B:B,B5) -> 2666 | AP5: =AL5-AN5-AO5 -> -30313.437
A6: 2 | B6: 赣J00236D | C6: 熊廷春 | D6: 杨发明 | E6: 广西-玉溪 | F6: 桂LA725挂 | G6: 重型半挂牵引车 | H6: =COUNTIFS(磅单!E:E,B6) -> 19 | I6: =SUMIFS(磅单!L:L,磅单!E:E,B6) -> 805.2 | J6: =SUMIFS(磅单!O:O,磅单!E:E,B6) -> 50229.42 | K6: =SUMIFS(月汇总!Y:Y,月汇总!B:B,B6) -> 285 | L6: =SUMIFS(月汇总!I:I,月汇总!B:B,B6,月汇总!C:C,F6) -> 0 | M6: =SUMIFS(月汇总!J:J,月汇总!B:B,B6,月汇总!C:C,F6) -> 16063.773 | N6: =M6/J6 -> 0.31980805 | O6: =M6/H6 -> 845.46174 | P6: =SUMIFS(月汇总!R:R,月汇总!B:B,B6)+SUMIFS(月汇总!S:S,月汇总!B:B,B6) -> 11800 | Q6: =P6/J6 -> 0.23492208 | R6: =SUMIFS(月汇总!Q:Q,月汇总!B:B,B6) -> 510 | S6: =R6/J6 -> 0.010153412 | T6: =SUMIFS(月汇总!N:N,月汇总!B:B,B6) -> 220.88197 | V6: =SUMIFS(月汇总!X:X,月汇总!B:B,B6) -> 0 | W6: =V6/J6 -> 0 | X6: =SUMIFS(月汇总!U:U,月汇总!B:B,B6) -> 467 | Y6: =X6/J6 -> 0.0092973401 | Z6: =SUMIFS(月汇总!O:O,月汇总!B:B,B6) -> 0 | AA6: =Z6/J6 -> 0 | AB6: =SUMIFS(月汇总!T:T,月汇总!B:B,B6) -> 120 | AC6: =AB6/J6 -> 0.0023890381 | AD6: =SUMIFS(月汇总!Z:Z,月汇总!B:B,B6) -> 3516.0594 | AE6: =AD6/J6 -> 0.07 | AF6: =SUMIFS(月汇总!AC:AC,月汇总!B:B,B6) -> 790.16393 | AG6: =AF6/J6 -> 0.015731098 | AH6: =SUMIFS(月汇总!V:V,月汇总!B:B,B6) -> 397.39246 | AI6: =AH6/J6 -> 0.0079115478 | AJ6: =M6+P6+R6+T6+V6+X6+Z6+AB6+AD6+AF6+AH6 -> 33885.271 | AK6: =SUMIFS(月汇总!AA:AA,月汇总!B:B,B6) -> 10600 | AL6: =J6-K6-L6-AJ6-AK6 -> 5459.1492 | AM6: =AL6/J6 -> 0.1086843 | AN6: =SUMIFS(月汇总!AB:AB,月汇总!B:B,B6) -> 3800 | AO6: =SUMIFS(月汇总!W:W,月汇总!B:B,B6) -> 2666 | AP6: =AL6-AN6-AO6 -> -1006.8508
A7: 3 | B7: 赣J05550D | C7: 任正勇 | D7: 杨发明 | E7: 广西-玉溪 | F7: 桂LD517挂 | G7: 重型半挂牵引车 | H7: =COUNTIFS(磅单!E:E,B7) -> 21 | I7: =SUMIFS(磅单!L:L,磅单!E:E,B7) -> 893.18 | J7: =SUMIFS(磅单!O:O,磅单!E:E,B7) -> 55301.38 | K7: =SUMIFS(月汇总!Y:Y,月汇总!B:B,B7) -> 315 | L7: =SUMIFS(月汇总!I:I,月汇总!B:B,B7,月汇总!C:C,F7) -> 0 | M7: =SUMIFS(月汇总!J:J,月汇总!B:B,B7,月汇总!C:C,F7) -> 17389.021 | N7: =M7/J7 -> 0.31444099 | O7: =M7/H7 -> 828.0486 | P7: =SUMIFS(月汇总!R:R,月汇总!B:B,B7)+SUMIFS(月汇总!S:S,月汇总!B:B,B7) -> 13200 | Q7: =P7/J7 -> 0.23869205 | R7: =SUMIFS(月汇总!Q:Q,月汇总!B:B,B7) -> 800 | S7: =R7/J7 -> 0.014466185 | T7: =SUMIFS(月汇总!N:N,月汇总!B:B,B7) -> 220.88197 | V7: =SUMIFS(月汇总!X:X,月汇总!B:B,B7) -> 0 | W7: =V7/J7 -> 0 | X7: =SUMIFS(月汇总!U:U,月汇总!B:B,B7) -> 544 | Y7: =X7/J7 -> 0.0098370059 | Z7: =SUMIFS(月汇总!O:O,月汇总!B:B,B7) -> 7130 | AA7: =Z7/J7 -> 0.12892987 | AB7: =SUMIFS(月汇总!T:T,月汇总!B:B,B7) -> 400 | AC7: =AB7/J7 -> 0.0072330926 | AD7: =SUMIFS(月汇总!Z:Z,月汇总!B:B,B7) -> 3871.0966 | AE7: =AD7/J7 -> 0.07 | AF7: =SUMIFS(月汇总!AC:AC,月汇总!B:B,B7) -> 790.16393 | AG7: =AF7/J7 -> 0.014288322 | AH7: =SUMIFS(月汇总!V:V,月汇总!B:B,B7) -> 397.39246 | AI7: =AH7/J7 -> 0.0071859411 | AJ7: =M7+P7+R7+T7+V7+X7+Z7+AB7+AD7+AF7+AH7 -> 44742.556 | AK7: =SUMIFS(月汇总!AA:AA,月汇总!B:B,B7) -> 10600 | AL7: =J7-K7-L7-AJ7-AK7 -> -356.17557 | AM7: =AL7/J7 -> -0.0064406272 | AN7: =SUMIFS(月汇总!AB:AB,月汇总!B:B,B7) -> 3800 | AO7: =SUMIFS(月汇总!W:W,月汇总!B:B,B7) -> 2666 | AP7: =AL7-AN7-AO7 -> -6822.1756
A8: 4 | B8: 赣J00607D | C8: 程大昌 | D8: 杨发明 | E8: 广西-玉溪 | F8: 桂LD396挂 | G8: 重型半挂牵引车 | H8: =COUNTIFS(磅单!E:E,B8) -> 19 | I8: =SUMIFS(磅单!L:L,磅单!E:E,B8) -> 782.99 | J8: =SUMIFS(磅单!O:O,磅单!E:E,B8) -> 46796.27 | K8: =SUMIFS(月汇总!Y:Y,月汇总!B:B,B8) -> 285 | L8: =SUMIFS(月汇总!I:I,月汇总!B:B,B8,月汇总!C:C,F8) -> 0 | M8: =SUMIFS(月汇总!J:J,月汇总!B:B,B8,月汇总!C:C,F8) -> 15004.904 | N8: =M8/J8 -> 0.32064315 | O8: =M8/H8 -> 789.73177 | P8: =SUMIFS(月汇总!R:R,月汇总!B:B,B8)+SUMIFS(月汇总!S:S,月汇总!B:B,B8) -> 11600 | Q8: =P8/J8 -> 0.247883 | R8: =SUMIFS(月汇总!Q:Q,月汇总!B:B,B8) -> 1120 | S8: =R8/J8 -> 0.023933531 | T8: =SUMIFS(月汇总!N:N,月汇总!B:B,B8) -> 220.88197 | V8: =SUMIFS(月汇总!X:X,月汇总!B:B,B8) -> 0 | W8: =V8/J8 -> 0 | X8: =SUMIFS(月汇总!U:U,月汇总!B:B,B8) -> 636 | Y8: =X8/J8 -> 0.013590827 | Z8: =SUMIFS(月汇总!O:O,月汇总!B:B,B8) -> 0 | AA8: =Z8/J8 -> 0 | AB8: =SUMIFS(月汇总!T:T,月汇总!B:B,B8) -> 440 | AC8: =AB8/J8 -> 0.0094024588 | AD8: =SUMIFS(月汇总!Z:Z,月汇总!B:B,B8) -> 3275.7389 | AE8: =AD8/J8 -> 0.07 | AF8: =SUMIFS(月汇总!AC:AC,月汇总!B:B,B8) -> 790.16393 | AG8: =AF8/J8 -> 0.016885191 | AH8: =SUMIFS(月汇总!V:V,月汇总!B:B,B8) -> 397.39246 | AI8: =AH8/J8 -> 0.0084919687 | AJ8: =M8+P8+R8+T8+V8+X8+Z8+AB8+AD8+AF8+AH8 -> 33485.081 | AK8: =SUMIFS(月汇总!AA:AA,月汇总!B:B,B8) -> 10600 | AL8: =J8-K8-L8-AJ8-AK8 -> 2426.1892 | AM8: =AL8/J8 -> 0.051845781 | AN8: =SUMIFS(月汇总!AB:AB,月汇总!B:B,B8) -> 3800 | AO8: =SUMIFS(月汇总!W:W,月汇总!B:B,B8) -> 2666 | AP8: =AL8-AN8-AO8 -> -4039.8108
A9: 5 | B9: 赣J00677D | C9: 付建东 | D9: 杨发明 | E9: 广西-玉溪 | F9: 桂LB829挂 | G9: 重型半挂牵引车 | H9: =COUNTIFS(磅单!E:E,B9) -> 20 | I9: =SUMIFS(磅单!L:L,磅单!E:E,B9) -> 820.18 | J9: =SUMIFS(磅单!O:O,磅单!E:E,B9) -> 50875.58 | K9: =SUMIFS(月汇总!Y:Y,月汇总!B:B,B9) -> 300 | L9: =SUMIFS(月汇总!I:I,月汇总!B:B,B9,月汇总!C:C,F9) -> 50 | M9: =SUMIFS(月汇总!J:J,月汇总!B:B,B9,月汇总!C:C,F9) -> 16613.933 | N9: =M9/J9 -> 0.32656006 | O9: =M9/H9 -> 830.69663 | P9: =SUMIFS(月汇总!R:R,月汇总!B:B,B9)+SUMIFS(月汇总!S:S,月汇总!B:B,B9) -> 12200 | Q9: =P9/J9 -> 0.23980071 | R9: =SUMIFS(月汇总!Q:Q,月汇总!B:B,B9) -> 670 | S9: =R9/J9 -> 0.013169383 | T9: =SUMIFS(月汇总!N:N,月汇总!B:B,B9) -> 220.88197 | V9: =SUMIFS(月汇总!X:X,月汇总!B:B,B9) -> 0 | W9: =V9/J9 -> 0 | X9: =SUMIFS(月汇总!U:U,月汇总!B:B,B9) -> 422 | Y9: =X9/J9 -> 0.0082947457 | Z9: =SUMIFS(月汇总!O:O,月汇总!B:B,B9) -> 7130 | AA9: =Z9/J9 -> 0.14014582 | AB9: =SUMIFS(月汇总!T:T,月汇总!B:B,B9) -> 200 | AC9: =AB9/J9 -> 0.0039311591 | AD9: =SUMIFS(月汇总!Z:Z,月汇总!B:B,B9) -> 3561.2906 | AE9: =AD9/J9 -> 0.07 | AF9: =SUMIFS(月汇总!AC:AC,月汇总!B:B,B9) -> 790.16393 | AG9: =AF9/J9 -> 0.015531301 | AH9: =SUMIFS(月汇总!V:V,月汇总!B:B,B9) -> 397.39246 | AI9: =AH9/J9 -> 0.0078110649 | AJ9: =M9+P9+R9+T9+V9+X9+Z9+AB9+AD9+AF9+AH9 -> 42205.661 | AK9: =SUMIFS(月汇总!AA:AA,月汇总!B:B,B9) -> 10600 | AL9: =J9-K9-L9-AJ9-AK9 -> -2280.0815 | AM9: =AL9/J9 -> -0.044816815 | AN9: =SUMIFS(月汇总!AB:AB,月汇总!B:B,B9) -> 3800 | AO9: =SUMIFS(月汇总!W:W,月汇总!B:B,B9) -> 2666 | AP9: =AL9-AN9-AO9 -> -8746.0815
A10: 6 | B10: 赣J01095D | C10: 张和平 | D10: 杨发明 | E10: 广西-玉溪 | F10: 桂LC705挂 | G10: 重型半挂牵引车 | H10: =COUNTIFS(磅单!E:E,B10) -> 19 | I10: =SUMIFS(磅单!L:L,磅单!E:E,B10) -> 769.79 | J10: =SUMIFS(磅单!O:O,磅单!E:E,B10) -> 48095.53 | K10: =SUMIFS(月汇总!Y:Y,月汇总!B:B,B10) -> 285 | L10: =SUMIFS(月汇总!I:I,月汇总!B:B,B10,月汇总!C:C,F10) -> 0 | M10: =SUMIFS(月汇总!J:J,月汇总!B:B,B10,月汇总!C:C,F10) -> 14132.489 | N10: =M10/J10 -> 0.29384204 | O10: =M10/H10 -> 743.81519 | P10: =SUMIFS(月汇总!R:R,月汇总!B:B,B10)+SUMIFS(月汇总!S:S,月汇总!B:B,B10) -> 11800 | Q10: =P10/J10 -> 0.24534505 | R10: =SUMIFS(月汇总!Q:Q,月汇总!B:B,B10) -> 415 | S10: =R10/J10 -> 0.0086286605 | T10: =SUMIFS(月汇总!N:N,月汇总!B:B,B10) -> 220.88197 | V10: =SUMIFS(月汇总!X:X,月汇总!B:B,B10) -> 0 | W10: =V10/J10 -> 0 | X10: =SUMIFS(月汇总!U:U,月汇总!B:B,B10) -> 581 | Y10: =X10/J10 -> 0.012080125 | Z10: =SUMIFS(月汇总!O:O,月汇总!B:B,B10) -> 900 | AA10: =Z10/J10 -> 0.018712758 | AB10: =SUMIFS(月汇总!T:T,月汇总!B:B,B10) -> 0 | AC10: =AB10/J10 -> 0 | AD10: =SUMIFS(月汇总!Z:Z,月汇总!B:B,B10) -> 3366.6871 | AE10: =AD10/J10 -> 0.07 | AF10: =SUMIFS(月汇总!AC:AC,月汇总!B:B,B10) -> 790.16393 | AG10: =AF10/J10 -> 0.016429051 | AH10: =SUMIFS(月汇总!V:V,月汇总!B:B,B10) -> 397.39246 | AI10: =AH10/J10 -> 0.0082625653 | AJ10: =M10+P10+R10+T10+V10+X10+Z10+AB10+AD10+AF10+AH10 -> 32603.614 | AK10: =SUMIFS(月汇总!AA:AA,月汇总!B:B,B10) -> 10600 | AL10: =J10-K10-L10-AJ10-AK10 -> 4606.9159 | AM10: =AL10/J10 -> 0.09578678 | AN10: =SUMIFS(月汇总!AB:AB,月汇总!B:B,B10) -> 3800 | AO10: =SUMIFS(月汇总!W:W,月汇总!B:B,B10) -> 2666 | AP10: =AL10-AN10-AO10 -> -1859.0841
A11: 7 | B11: 赣J03136D | C11: 朱家访 | D11: 杨发明 | E11: 广西-玉溪 | F11: 桂L9856挂 | G11: 重型半挂牵引车 | H11: =COUNTIFS(磅单!E:E,B11) -> 18 | I11: =SUMIFS(磅单!L:L,磅单!E:E,B11) -> 750.31 | J11: =SUMIFS(磅单!O:O,磅单!E:E,B11) -> 46013.89 | K11: =SUMIFS(月汇总!Y:Y,月汇总!B:B,B11) -> 270 | L11: =SUMIFS(月汇总!I:I,月汇总!B:B,B11,月汇总!C:C,F11) -> 0 | M11: =SUMIFS(月汇总!J:J,月汇总!B:B,B11,月汇总!C:C,F11) -> 15027.95 | N11: =M11/J11 -> 0.32659595 | O11: =M11/H11 -> 834.88612 | P11: =SUMIFS(月汇总!R:R,月汇总!B:B,B11)+SUMIFS(月汇总!S:S,月汇总!B:B,B11) -> 11800 | Q11: =P11/J11 -> 0.2564443 | R11: =SUMIFS(月汇总!Q:Q,月汇总!B:B,B11) -> 50 | S11: =R11/J11 -> 0.0010866284 | T11: =SUMIFS(月汇总!N:N,月汇总!B:B,B11) -> 220.88197 | V11: =SUMIFS(月汇总!X:X,月汇总!B:B,B11) -> 0 | W11: =V11/J11 -> 0 | X11: =SUMIFS(月汇总!U:U,月汇总!B:B,B11) -> 480 | Y11: =X11/J11 -> 0.010431633 | Z11: =SUMIFS(月汇总!O:O,月汇总!B:B,B11) -> 900 | AA11: =Z11/J11 -> 0.019559311 | AB11: =SUMIFS(月汇总!T:T,月汇总!B:B,B11) -> 210 | AC11: =AB11/J11 -> 0.0045638393 | AD11: =SUMIFS(月汇总!Z:Z,月汇总!B:B,B11) -> 3406.1335 | AE11: =AD11/J11 -> 0.074024028 | AF11: =SUMIFS(月汇总!AC:AC,月汇总!B:B,B11) -> 790.16393 | AG11: =AF11/J11 -> 0.017172292 | AH11: =SUMIFS(月汇总!V:V,月汇总!B:B,B11) -> 397.39246 | AI11: =AH11/J11 -> 0.0086363587 | AJ11: =M11+P11+R11+T11+V11+X11+Z11+AB11+AD11+AF11+AH11 -> 33282.522 | AK11: =SUMIFS(月汇总!AA:AA,月汇总!B:B,B11) -> 10600 | AL11: =J11-K11-L11-AJ11-AK11 -> 1861.368 | AM11: =AL11/J11 -> 0.040452308 | AN11: =SUMIFS(月汇总!AB:AB,月汇总!B:B,B11) -> 3800 | AO11: =SUMIFS(月汇总!W:W,月汇总!B:B,B11) -> 2666 | AP11: =AL11-AN11-AO11 -> -4604.632
A12: 8 | B12: 赣J03688D | C12: 刘小福 | D12: 杨发明 | E12: 广西-玉溪 | F12: 桂LA935挂 | G12: 重型半挂牵引车 | H12: =COUNTIFS(磅单!E:E,B12) -> 22 | I12: =SUMIFS(磅单!L:L,磅单!E:E,B12) -> 928.88 | J12: =SUMIFS(磅单!O:O,磅单!E:E,B12) -> 58792.78 | K12: =SUMIFS(月汇总!Y:Y,月汇总!B:B,B12) -> 330 | L12: =SUMIFS(月汇总!I:I,月汇总!B:B,B12,月汇总!C:C,F12) -> 0 | M12: =SUMIFS(月汇总!J:J,月汇总!B:B,B12,月汇总!C:C,F12) -> 16765.748 | N12: =M12/J12 -> 0.28516679 | O12: =M12/H12 -> 762.07948 | P12: =SUMIFS(月汇总!R:R,月汇总!B:B,B12)+SUMIFS(月汇总!S:S,月汇总!B:B,B12) -> 15000 | Q12: =P12/J12 -> 0.25513337 | R12: =SUMIFS(月汇总!Q:Q,月汇总!B:B,B12) -> 1203 | S12: =R12/J12 -> 0.020461696 | T12: =SUMIFS(月汇总!N:N,月汇总!B:B,B12) -> 220.88197 | V12: =SUMIFS(月汇总!X:X,月汇总!B:B,B12) -> 0 | W12: =V12/J12 -> 0 | X12: =SUMIFS(月汇总!U:U,月汇总!B:B,B12) -> 711 | Y12: =X12/J12 -> 0.012093322 | Z12: =SUMIFS(月汇总!O:O,月汇总!B:B,B12) -> 0 | AA12: =Z12/J12 -> 0 | AB12: =SUMIFS(月汇总!T:T,月汇总!B:B,B12) -> 420 | AC12: =AB12/J12 -> 0.0071437343 | AD12: =SUMIFS(月汇总!Z:Z,月汇总!B:B,B12) -> 4115.4946 | AE12: =AD12/J12 -> 0.07 | AF12: =SUMIFS(月汇总!AC:AC,月汇总!B:B,B12) -> 790.16393 | AG12: =AF12/J12 -> 0.013439812 | AH12: =SUMIFS(月汇总!V:V,月汇总!B:B,B12) -> 397.39246 | AI12: =AH12/J12 -> 0.0067592051 | AJ12: =M12+P12+R12+T12+V12+X12+Z12+AB12+AD12+AF12+AH12 -> 39623.681 | AK12: =SUMIFS(月汇总!AA:AA,月汇总!B:B,B12) -> 10600 | AL12: =J12-K12-L12-AJ12-AK12 -> 8239.0986 | AM12: =AL12/J12 -> 0.14013793 | AN12: =SUMIFS(月汇总!AB:AB,月汇总!B:B,B12) -> 3800 | AO12: =SUMIFS(月汇总!W:W,月汇总!B:B,B12) -> 2666 | AP12: =AL12-AN12-AO12 -> 1773.0986
A13: 9 | B13: 赣J07535D | C13: 李家宝 | D13: 杨发明 | E13: 广西-玉溪 | F13: 桂LB307挂 | G13: 重型半挂牵引车 | H13: =COUNTIFS(磅单!E:E,B13) -> 21 | I13: =SUMIFS(磅单!L:L,磅单!E:E,B13) -> 874.61 | J13: =SUMIFS(磅单!O:O,磅单!E:E,B13) -> 55429.23 | K13: =SUMIFS(月汇总!Y:Y,月汇总!B:B,B13) -> 315 | L13: =SUMIFS(月汇总!I:I,月汇总!B:B,B13,月汇总!C:C,F13) -> 0 | M13: =SUMIFS(月汇总!J:J,月汇总!B:B,B13,月汇总!C:C,F13) -> 14114.09 | N13: =M13/J13 -> 0.25463261 | O13: =M13/H13 -> 672.0995 | P13: =SUMIFS(月汇总!R:R,月汇总!B:B,B13)+SUMIFS(月汇总!S:S,月汇总!B:B,B13) -> 13000 | Q13: =P13/J13 -> 0.2345333 | R13: =SUMIFS(月汇总!Q:Q,月汇总!B:B,B13) -> 620 | S13: =R13/J13 -> 0.011185434 | T13: =SUMIFS(月汇总!N:N,月汇总!B:B,B13) -> 220.88197 | V13: =SUMIFS(月汇总!X:X,月汇总!B:B,B13) -> 0 | W13: =V13/J13 -> 0 | X13: =SUMIFS(月汇总!U:U,月汇总!B:B,B13) -> 613 | Y13: =X13/J13 -> 0.011059147 | Z13: =SUMIFS(月汇总!O:O,月汇总!B:B,B13) -> 0 | AA13: =Z13/J13 -> 0 | AB13: =SUMIFS(月汇总!T:T,月汇总!B:B,B13) -> 0 | AC13: =AB13/J13 -> 0 | AD13: =SUMIFS(月汇总!Z:Z,月汇总!B:B,B13) -> 3880.0461 | AE13: =AD13/J13 -> 0.07 | AF13: =SUMIFS(月汇总!AC:AC,月汇总!B:B,B13) -> 790.16393 | AG13: =AF13/J13 -> 0.014255366 | AH13: =SUMIFS(月汇总!V:V,月汇总!B:B,B13) -> 397.39246 | AI13: =AH13/J13 -> 0.0071693664 | AJ13: =M13+P13+R13+T13+V13+X13+Z13+AB13+AD13+AF13+AH13 -> 33635.574 | AK13: =SUMIFS(月汇总!AA:AA,月汇总!B:B,B13) -> 10600 | AL13: =J13-K13-L13-AJ13-AK13 -> 10878.656 | AM13: =AL13/J13 -> 0.19626208 | AN13: =SUMIFS(月汇总!AB:AB,月汇总!B:B,B13) -> 3800 | AO13: =SUMIFS(月汇总!W:W,月汇总!B:B,B13) -> 2666 | AP13: =AL13-AN13-AO13 -> 4412.656
A14: 10 | B14: 赣J08536D | C14: 李建祥 | D14: 杨发明 | E14: 广西-玉溪 | F14: 桂LD179挂 | G14: 重型半挂牵引车 | H14: =COUNTIFS(磅单!E:E,B14) -> 16 | I14: =SUMIFS(磅单!L:L,磅单!E:E,B14) -> 673.98 | J14: =SUMIFS(磅单!O:O,磅单!E:E,B14) -> 44638.62 | K14: =SUMIFS(月汇总!Y:Y,月汇总!B:B,B14) -> 240 | L14: =SUMIFS(月汇总!I:I,月汇总!B:B,B14,月汇总!C:C,F14) -> 0 | M14: =SUMIFS(月汇总!J:J,月汇总!B:B,B14,月汇总!C:C,F14) -> 15202.365 | N14: =M14/J14 -> 0.34056531 | O14: =M14/H14 -> 950.14784 | P14: =SUMIFS(月汇总!R:R,月汇总!B:B,B14)+SUMIFS(月汇总!S:S,月汇总!B:B,B14) -> 11400 | Q14: =P14/J14 -> 0.25538424 | R14: =SUMIFS(月汇总!Q:Q,月汇总!B:B,B14) -> 370 | S14: =R14/J14 -> 0.0082887867 | T14: =SUMIFS(月汇总!N:N,月汇总!B:B,B14) -> 220.88197 | V14: =SUMIFS(月汇总!X:X,月汇总!B:B,B14) -> 0 | W14: =V14/J14 -> 0 | X14: =SUMIFS(月汇总!U:U,月汇总!B:B,B14) -> 3194 | Y14: =X14/J14 -> 0.071552391 | Z14: =SUMIFS(月汇总!O:O,月汇总!B:B,B14) -> 0 | AA14: =Z14/J14 -> 0 | AB14: =SUMIFS(月汇总!T:T,月汇总!B:B,B14) -> 0 | AC14: =AB14/J14 -> 0 | AD14: =SUMIFS(月汇总!Z:Z,月汇总!B:B,B14) -> 3124.7034 | AE14: =AD14/J14 -> 0.07 | AF14: =SUMIFS(月汇总!AC:AC,月汇总!B:B,B14) -> 790.16393 | AG14: =AF14/J14 -> 0.017701352 | AH14: =SUMIFS(月汇总!V:V,月汇总!B:B,B14) -> 397.39246 | AI14: =AH14/J14 -> 0.008902436 | AJ14: =M14+P14+R14+T14+V14+X14+Z14+AB14+AD14+AF14+AH14 -> 34699.507 | AK14: =SUMIFS(月汇总!AA:AA,月汇总!B:B,B14) -> 10600 | AL14: =J14-K14-L14-AJ14-AK14 -> -900.88717 | AM14: =AL14/J14 -> -0.020181788 | AN14: =SUMIFS(月汇总!AB:AB,月汇总!B:B,B14) -> 3800 | AO14: =SUMIFS(月汇总!W:W,月汇总!B:B,B14) -> 2666 | AP14: =AL14-AN14-AO14 -> -7366.8872
A15: 11 | B15: 赣J05857D | C15: 高洪伟 | D15: 杨发明 | E15: 广西-玉溪 | F15: 桂LB659挂 | G15: 重型半挂牵引车 | H15: =COUNTIFS(磅单!E:E,B15) -> 19 | I15: =SUMIFS(磅单!L:L,磅单!E:E,B15) -> 798.41 | J15: =SUMIFS(磅单!O:O,磅单!E:E,B15) -> 48640.05 | K15: =SUMIFS(月汇总!Y:Y,月汇总!B:B,B15) -> 285 | L15: =SUMIFS(月汇总!I:I,月汇总!B:B,B15,月汇总!C:C,F15) -> 0 | M15: =SUMIFS(月汇总!J:J,月汇总!B:B,B15,月汇总!C:C,F15) -> 14817.425 | N15: =M15/J15 -> 0.30463425 | O15: =M15/H15 -> 779.86447 | P15: =SUMIFS(月汇总!R:R,月汇总!B:B,B15)+SUMIFS(月汇总!S:S,月汇总!B:B,B15) -> 11800 | Q15: =P15/J15 -> 0.24259843 | R15: =SUMIFS(月汇总!Q:Q,月汇总!B:B,B15) -> 2190 | S15: =R15/J15 -> 0.045024625 | T15: =SUMIFS(月汇总!N:N,月汇总!B:B,B15) -> 220.88197 | V15: =SUMIFS(月汇总!X:X,月汇总!B:B,B15) -> 0 | W15: =V15/J15 -> 0 | X15: =SUMIFS(月汇总!U:U,月汇总!B:B,B15) -> 395 | Y15: =X15/J15 -> 0.0081208798 | Z15: =SUMIFS(月汇总!O:O,月汇总!B:B,B15) -> 50 | AA15: =Z15/J15 -> 0.0010279595 | AB15: =SUMIFS(月汇总!T:T,月汇总!B:B,B15) -> 200 | AC15: =AB15/J15 -> 0.0041118379 | AD15: =SUMIFS(月汇总!Z:Z,月汇总!B:B,B15) -> 3404.8035 | AE15: =AD15/J15 -> 0.07 | AF15: =SUMIFS(月汇总!AC:AC,月汇总!B:B,B15) -> 790.16393 | AG15: =AF15/J15 -> 0.01624513 | AH15: =SUMIFS(月汇总!V:V,月汇总!B:B,B15) -> 397.39246 | AI15: =AH15/J15 -> 0.0081700668 | AJ15: =M15+P15+R15+T15+V15+X15+Z15+AB15+AD15+AF15+AH15 -> 34265.667 | AK15: =SUMIFS(月汇总!AA:AA,月汇总!B:B,B15) -> 10600 | AL15: =J15-K15-L15-AJ15-AK15 -> 3489.3831 | AM15: =AL15/J15 -> 0.071738889 | AN15: =SUMIFS(月汇总!AB:AB,月汇总!B:B,B15) -> 3800 | AO15: =SUMIFS(月汇总!W:W,月汇总!B:B,B15) -> 2666 | AP15: =AL15-AN15-AO15 -> -2976.6169
A16: 12 | B16: 赣J06519D | C16: 冯育柱 | D16: 杨发明 | E16: 广西-玉溪 | F16: 桂L5759挂 | G16: 重型半挂牵引车 | H16: =COUNTIFS(磅单!E:E,B16) -> 25 | I16: =SUMIFS(磅单!L:L,磅单!E:E,B16) -> 1015.87 | J16: =SUMIFS(磅单!O:O,磅单!E:E,B16) -> 64387.11 | K16: =SUMIFS(月汇总!Y:Y,月汇总!B:B,B16) -> 375 | L16: =SUMIFS(月汇总!I:I,月汇总!B:B,B16,月汇总!C:C,F16) -> 0 | M16: =SUMIFS(月汇总!J:J,月汇总!B:B,B16,月汇总!C:C,F16) -> 20084.735 | N16: =M16/J16 -> 0.3119372 | O16: =M16/H16 -> 803.3894 | P16: =SUMIFS(月汇总!R:R,月汇总!B:B,B16)+SUMIFS(月汇总!S:S,月汇总!B:B,B16) -> 15600 | Q16: =P16/J16 -> 0.24228452 | R16: =SUMIFS(月汇总!Q:Q,月汇总!B:B,B16) -> 2396 | S16: =R16/J16 -> 0.037212417 | T16: =SUMIFS(月汇总!N:N,月汇总!B:B,B16) -> 220.88197 | V16: =SUMIFS(月汇总!X:X,月汇总!B:B,B16) -> 0 | W16: =V16/J16 -> 0 | X16: =SUMIFS(月汇总!U:U,月汇总!B:B,B16) -> 606 | Y16: =X16/J16 -> 0.0094118217 | Z16: =SUMIFS(月汇总!O:O,月汇总!B:B,B16) -> 950 | AA16: =Z16/J16 -> 0.014754506 | AB16: =SUMIFS(月汇总!T:T,月汇总!B:B,B16) -> 220 | AC16: =AB16/J16 -> 0.003416833 | AD16: =SUMIFS(月汇总!Z:Z,月汇总!B:B,B16) -> 4507.0977 | AE16: =AD16/J16 -> 0.07 | AF16: =SUMIFS(月汇总!AC:AC,月汇总!B:B,B16) -> 790.16393 | AG16: =AF16/J16 -> 0.012272083 | AH16: =SUMIFS(月汇总!V:V,月汇总!B:B,B16) -> 397.39246 | AI16: =AH16/J16 -> 0.0061719257 | AJ16: =M16+P16+R16+T16+V16+X16+Z16+AB16+AD16+AF16+AH16 -> 45772.271 | AK16: =SUMIFS(月汇总!AA:AA,月汇总!B:B,B16) -> 10600 | AL16: =J16-K16-L16-AJ16-AK16 -> 7639.839 | AM16: =AL16/J16 -> 0.11865479 | AN16: =SUMIFS(月汇总!AB:AB,月汇总!B:B,B16) -> 3800 | AO16: =SUMIFS(月汇总!W:W,月汇总!B:B,B16) -> 2666 | AP16: =AL16-AN16-AO16 -> 1173.839
... A25: 21 | B25: 沪A04114D | C25: 李玉红 | D25: 杨发明 | E25: 广西-玉溪 | F25: 桂LB957挂 | G25: 重型半挂牵引车 | H25: =COUNTIFS(磅单!E:E,B25) -> 17 | I25: =SUMIFS(磅单!L:L,磅单!E:E,B25) -> 722.21 | J25: =SUMIFS(磅单!O:O,磅单!E:E,B25) -> 47707.93 | K25: =SUMIFS(月汇总!Y:Y,月汇总!B:B,B25) -> 255 | L25: =SUMIFS(月汇总!I:I,月汇总!B:B,B25,月汇总!C:C,F25) -> 0 | M25: =SUMIFS(月汇总!J:J,月汇总!B:B,B25,月汇总!C:C,F25) -> 13353.994 | N25: =M25/J25 -> 0.27991141 | O25: =M25/H25 -> 785.52906 | P25: =SUMIFS(月汇总!R:R,月汇总!B:B,B25)+SUMIFS(月汇总!S:S,月汇总!B:B,B25) -> 11200 | Q25: =P25/J25 -> 0.23476181 | R25: =SUMIFS(月汇总!Q:Q,月汇总!B:B,B25) -> 400 | S25: =R25/J25 -> 0.0083843504 | T25: =SUMIFS(月汇总!N:N,月汇总!B:B,B25) -> 220.88197 | V25: =SUMIFS(月汇总!X:X,月汇总!B:B,B25) -> 0 | W25: =V25/J25 -> 0 | X25: =SUMIFS(月汇总!U:U,月汇总!B:B,B25) -> 554 | Y25: =X25/J25 -> 0.011612325 | Z25: =SUMIFS(月汇总!O:O,月汇总!B:B,B25) -> 1000 | AA25: =Z25/J25 -> 0.020960876 | AB25: =SUMIFS(月汇总!T:T,月汇总!B:B,B25) -> 440 | AC25: =AB25/J25 -> 0.0092227854 | AD25: =SUMIFS(月汇总!Z:Z,月汇总!B:B,B25) -> 3339.5551 | AE25: =AD25/J25 -> 0.07 | AF25: =SUMIFS(月汇总!AC:AC,月汇总!B:B,B25) -> 790.16393 | AG25: =AF25/J25 -> 0.016562528 | AH25: =SUMIFS(月汇总!V:V,月汇总!B:B,B25) -> 397.39246 | AI25: =AH25/J25 -> 0.008329694 | AJ25: =M25+P25+R25+T25+V25+X25+Z25+AB25+AD25+AF25+AH25 -> 31695.987 | AK25: =SUMIFS(月汇总!AA:AA,月汇总!B:B,B25) -> 10600 | AL25: =J25-K25-L25-AJ25-AK25 -> 5156.9425 | AM25: =AL25/J25 -> 0.10809403 | AN25: =SUMIFS(月汇总!AB:AB,月汇总!B:B,B25) -> 3800 | AO25: =SUMIFS(月汇总!W:W,月汇总!B:B,B25) -> 2666 | AP25: =AL25-AN25-AO25 -> -1309.0575
A26: 22 | B26: 赣J08767D | C26: 何仕财 | D26: 杨发明 | E26: 广西-玉溪 | F26: 桂LA357挂 | G26: 重型半挂牵引车 | H26: =COUNTIFS(磅单!E:E,B26) -> 23 | I26: =SUMIFS(磅单!L:L,磅单!E:E,B26) -> 949.84 | J26: =SUMIFS(磅单!O:O,磅单!E:E,B26) -> 59389.6 | K26: =SUMIFS(月汇总!Y:Y,月汇总!B:B,B26) -> 345 | L26: =SUMIFS(月汇总!I:I,月汇总!B:B,B26,月汇总!C:C,F26) -> 0 | M26: =SUMIFS(月汇总!J:J,月汇总!B:B,B26,月汇总!C:C,F26) -> 19713.958 | N26: =M26/J26 -> 0.33194294 | O26: =M26/H26 -> 857.12862 | P26: =SUMIFS(月汇总!R:R,月汇总!B:B,B26)+SUMIFS(月汇总!S:S,月汇总!B:B,B26) -> 14400 | Q26: =P26/J26 -> 0.24246669 | R26: =SUMIFS(月汇总!Q:Q,月汇总!B:B,B26) -> 455 | S26: =R26/J26 -> 0.007661274 | T26: =SUMIFS(月汇总!N:N,月汇总!B:B,B26) -> 220.88197 | V26: =SUMIFS(月汇总!X:X,月汇总!B:B,B26) -> 0 | X26: =SUMIFS(月汇总!U:U,月汇总!B:B,B26) -> 568.6 | Y26: =X26/J26 -> 0.0095740668 | Z26: =SUMIFS(月汇总!O:O,月汇总!B:B,B26) -> 0 | AA26: =Z26/J26 -> 0 | AB26: =SUMIFS(月汇总!T:T,月汇总!B:B,B26) -> 260 | AC26: =AB26/J26 -> 0.0043778709 | AD26: =SUMIFS(月汇总!Z:Z,月汇总!B:B,B26) -> 4157.272 | AE26: =AD26/J26 -> 0.07 | AF26: =SUMIFS(月汇总!AC:AC,月汇总!B:B,B26) -> 790.16393 | AG26: =AF26/J26 -> 0.013304753 | AH26: =SUMIFS(月汇总!V:V,月汇总!B:B,B26) -> 397.39246 | AI26: =AH26/J26 -> 0.0066912803 | AJ26: =M26+P26+R26+T26+V26+X26+Z26+AB26+AD26+AF26+AH26 -> 40963.269 | AK26: =SUMIFS(月汇总!AA:AA,月汇总!B:B,B26) -> 10600 | AL26: =J26-K26-L26-AJ26-AK26 -> 7481.3314 | AM26: =AL26/J26 -> 0.1259704 | AN26: =SUMIFS(月汇总!AB:AB,月汇总!B:B,B26) -> 3800 | AO26: =SUMIFS(月汇总!W:W,月汇总!B:B,B26) -> 2666 | AP26: =AL26-AN26-AO26 -> 1015.3314
A27: 23 | B27: 赣J03528D | C27: 罗晶 | D27: 杨发明 | E27: 广西-玉溪 | F27: 桂LE308挂 | G27: 重型半挂牵引车 | H27: =COUNTIFS(磅单!E:E,B27) -> 21 | I27: =SUMIFS(磅单!L:L,磅单!E:E,B27) -> 888.56 | J27: =SUMIFS(磅单!O:O,磅单!E:E,B27) -> 57045.58 | K27: =SUMIFS(月汇总!Y:Y,月汇总!B:B,B27) -> 315 | L27: =SUMIFS(月汇总!I:I,月汇总!B:B,B27,月汇总!C:C,F27) -> 0 | M27: =SUMIFS(月汇总!J:J,月汇总!B:B,B27,月汇总!C:C,F27) -> 15543.134 | N27: =M27/J27 -> 0.27246869 | O27: =M27/H27 -> 740.14925 | P27: =SUMIFS(月汇总!R:R,月汇总!B:B,B27)+SUMIFS(月汇总!S:S,月汇总!B:B,B27) -> 13200 | Q27: =P27/J27 -> 0.23139391 | R27: =SUMIFS(月汇总!Q:Q,月汇总!B:B,B27) -> 570 | S27: =R27/J27 -> 0.0099920099 | T27: =SUMIFS(月汇总!N:N,月汇总!B:B,B27) -> 220.88197 | V27: =SUMIFS(月汇总!X:X,月汇总!B:B,B27) -> 0 | X27: =SUMIFS(月汇总!U:U,月汇总!B:B,B27) -> 608 | Y27: =X27/J27 -> 0.010658144 | Z27: =SUMIFS(月汇总!O:O,月汇总!B:B,B27) -> 0 | AA27: =Z27/J27 -> 0 | AB27: =SUMIFS(月汇总!T:T,月汇总!B:B,B27) -> 200 | AC27: =AB27/J27 -> 0.0035059684 | AD27: =SUMIFS(月汇总!Z:Z,月汇总!B:B,B27) -> 3993.1906 | AE27: =AD27/J27 -> 0.07 | AF27: =SUMIFS(月汇总!AC:AC,月汇总!B:B,B27) -> 790.16393 | AG27: =AF27/J27 -> 0.013851449 | AH27: =SUMIFS(月汇总!V:V,月汇总!B:B,B27) -> 397.39246 | AI27: =AH27/J27 -> 0.006966227 | AJ27: =M27+P27+R27+T27+V27+X27+Z27+AB27+AD27+AF27+AH27 -> 35522.763 | AK27: =SUMIFS(月汇总!AA:AA,月汇总!B:B,B27) -> 10600 | AL27: =J27-K27-L27-AJ27-AK27 -> 10607.817 | AM27: =AL27/J27 -> 0.18595335 | AN27: =SUMIFS(月汇总!AB:AB,月汇总!B:B,B27) -> 3800 | AO27: =SUMIFS(月汇总!W:W,月汇总!B:B,B27) -> 2666 | AP27: =AL27-AN27-AO27 -> 4141.8168
A28: 24 | B28: 赣J03373D | C28: 陆金城 | D28: 袁俊杰 | E28: 广西-玉溪 | F28: 桂LC575挂 | G28: 重型半挂牵引车 | H28: =COUNTIFS(磅单!E:E,B28) -> 4 | I28: =SUMIFS(磅单!L:L,磅单!E:E,B28) -> 167.72 | J28: =SUMIFS(磅单!O:O,磅单!E:E,B28) -> 11193.96 | K28: =SUMIFS(月汇总!Y:Y,月汇总!B:B,B28) -> 60 | L28: =SUMIFS(月汇总!I:I,月汇总!B:B,B28,月汇总!C:C,F28) -> 50 | M28: =SUMIFS(月汇总!J:J,月汇总!B:B,B28,月汇总!C:C,F28) -> 5252.5871 | N28: =M28/J28 -> 0.46923404 | O28: =M28/H28 -> 1313.1468 | P28: =SUMIFS(月汇总!R:R,月汇总!B:B,B28)+SUMIFS(月汇总!S:S,月汇总!B:B,B28) -> 3000 | Q28: =P28/J28 -> 0.26800167 | R28: =SUMIFS(月汇总!Q:Q,月汇总!B:B,B28) -> 295 | S28: =R28/J28 -> 0.026353498 | T28: =SUMIFS(月汇总!N:N,月汇总!B:B,B28) -> 220.88197 | V28: =SUMIFS(月汇总!X:X,月汇总!B:B,B28) -> 0 | X28: =SUMIFS(月汇总!U:U,月汇总!B:B,B28) -> 160 | Y28: =X28/J28 -> 0.014293423 | Z28: =SUMIFS(月汇总!O:O,月汇总!B:B,B28) -> 0 | AA28: =Z28/J28 -> 0 | AB28: =SUMIFS(月汇总!T:T,月汇总!B:B,B28) -> 200 | AC28: =AB28/J28 -> 0.017866778 | AD28: =SUMIFS(月汇总!Z:Z,月汇总!B:B,B28) -> 783.5772 | AE28: =AD28/J28 -> 0.07 | AF28: =SUMIFS(月汇总!AC:AC,月汇总!B:B,B28) -> 790.16393 | AG28: =AF28/J28 -> 0.070588419 | AH28: =SUMIFS(月汇总!V:V,月汇总!B:B,B28) -> 397.39246 | AI28: =AH28/J28 -> 0.035500615 | AJ28: =M28+P28+R28+T28+V28+X28+Z28+AB28+AD28+AF28+AH28 -> 11099.603 | AK28: =SUMIFS(月汇总!AA:AA,月汇总!B:B,B28) -> 10600 | AL28: =J28-K28-L28-AJ28-AK28 -> -10615.643 | AM28: =AL28/J28 -> -0.94833666 | AN28: =SUMIFS(月汇总!AB:AB,月汇总!B:B,B28) -> 3800 | AO28: =SUMIFS(月汇总!W:W,月汇总!B:B,B28) -> 2666 | AP28: =AL28-AN28-AO28 -> -17081.643
A29: 25 | B29: 赣J02525D | C29: 杨仁华 | D29: 杨发明 | E29: 广西-玉溪 | F29: 桂LB297挂 | G29: 重型半挂牵引车 | H29: =COUNTIFS(磅单!E:E,B29) -> 2 | I29: =SUMIFS(磅单!L:L,磅单!E:E,B29) -> 85.91 | J29: =SUMIFS(磅单!O:O,磅单!E:E,B29) -> 5499.59 | K29: =SUMIFS(月汇总!Y:Y,月汇总!B:B,B29) -> 30 | L29: =SUMIFS(月汇总!I:I,月汇总!B:B,B29,月汇总!C:C,F29) -> 0 | M29: =SUMIFS(月汇总!J:J,月汇总!B:B,B29,月汇总!C:C,F29) -> 2495.5028 | N29: =M29/J29 -> 0.45376161 | O29: =M29/H29 -> 1247.7514 | P29: =SUMIFS(月汇总!R:R,月汇总!B:B,B29)+SUMIFS(月汇总!S:S,月汇总!B:B,B29) -> 1200 | Q29: =P29/J29 -> 0.21819808 | R29: =SUMIFS(月汇总!Q:Q,月汇总!B:B,B29) -> 300 | S29: =R29/J29 -> 0.054549521 | T29: =SUMIFS(月汇总!N:N,月汇总!B:B,B29) -> 220.88197 | V29: =SUMIFS(月汇总!X:X,月汇总!B:B,B29) -> 0 | X29: =SUMIFS(月汇总!U:U,月汇总!B:B,B29) -> 417 | Y29: =X29/J29 -> 0.075823834 | Z29: =SUMIFS(月汇总!O:O,月汇总!B:B,B29) -> 0 | AA29: =Z29/J29 -> 0 | AB29: =SUMIFS(月汇总!T:T,月汇总!B:B,B29) -> 200 | AC29: =AB29/J29 -> 0.036366347 | AD29: =SUMIFS(月汇总!Z:Z,月汇总!B:B,B29) -> 384.9713 | AE29: =AD29/J29 -> 0.07 | AF29: =SUMIFS(月汇总!AC:AC,月汇总!B:B,B29) -> 790.16393 | AG29: =AF29/J29 -> 0.14367688 | AH29: =SUMIFS(月汇总!V:V,月汇总!B:B,B29) -> 397.39246 | AI29: =AH29/J29 -> 0.072258561 | AJ29: =M29+P29+R29+T29+V29+X29+Z29+AB29+AD29+AF29+AH29 -> 6405.9125 | AK29: =SUMIFS(月汇总!AA:AA,月汇总!B:B,B29) -> 10600 | AL29: =J29-K29-L29-AJ29-AK29 -> -11536.322 | AM29: =AL29/J29 -> -2.0976695 | AN29: =SUMIFS(月汇总!AB:AB,月汇总!B:B,B29) -> 3800 | AO29: =SUMIFS(月汇总!W:W,月汇总!B:B,B29) -> 2666 | AP29: =AL29-AN29-AO29 -> -18002.322
A30: 26 | B30: 赣J05379D | C30: 昝建伟 | D30: 杨发明 | E30: 广西-玉溪 | F30: 桂LC316挂 | G30: 重型半挂牵引车 | H30: =COUNTIFS(磅单!E:E,B30) -> 17 | I30: =SUMIFS(磅单!L:L,磅单!E:E,B30) -> 685.49 | J30: =SUMIFS(磅单!O:O,磅单!E:E,B30) -> 44813.27 | K30: =SUMIFS(月汇总!Y:Y,月汇总!B:B,B30) -> 255 | L30: =SUMIFS(月汇总!I:I,月汇总!B:B,B30,月汇总!C:C,F30) -> 50 | M30: =SUMIFS(月汇总!J:J,月汇总!B:B,B30,月汇总!C:C,F30) -> 14525.358 | N30: =M30/J30 -> 0.32413073 | O30: =M30/H30 -> 854.43282 | P30: =SUMIFS(月汇总!R:R,月汇总!B:B,B30)+SUMIFS(月汇总!S:S,月汇总!B:B,B30) -> 11000 | Q30: =P30/J30 -> 0.24546301 | R30: =SUMIFS(月汇总!Q:Q,月汇总!B:B,B30) -> 270 | S30: =R30/J30 -> 0.0060250011 | T30: =SUMIFS(月汇总!N:N,月汇总!B:B,B30) -> 220.88197 | V30: =SUMIFS(月汇总!X:X,月汇总!B:B,B30) -> 0 | X30: =SUMIFS(月汇总!U:U,月汇总!B:B,B30) -> 456 | Y30: =X30/J30 -> 0.010175557 | Z30: =SUMIFS(月汇总!O:O,月汇总!B:B,B30) -> 6080 | AA30: =Z30/J30 -> 0.1356741 | AB30: =SUMIFS(月汇总!T:T,月汇总!B:B,B30) -> 200 | AC30: =AB30/J30 -> 0.0044629638 | AD30: =SUMIFS(月汇总!Z:Z,月汇总!B:B,B30) -> 3136.9289 | AE30: =AD30/J30 -> 0.07 | AF30: =SUMIFS(月汇总!AC:AC,月汇总!B:B,B30) -> 790.16393 | AG30: =AF30/J30 -> 0.017632365 | AH30: =SUMIFS(月汇总!V:V,月汇总!B:B,B30) -> 397.39246 | AI30: =AH30/J30 -> 0.0088677407 | AJ30: =M30+P30+R30+T30+V30+X30+Z30+AB30+AD30+AF30+AH30 -> 37076.725 | AK30: =SUMIFS(月汇总!AA:AA,月汇总!B:B,B30) -> 10600 | AL30: =J30-K30-L30-AJ30-AK30 -> -3168.4553 | AM30: =AL30/J30 -> -0.070703505 | AN30: =SUMIFS(月汇总!AB:AB,月汇总!B:B,B30) -> 3800 | AO30: =SUMIFS(月汇总!W:W,月汇总!B:B,B30) -> 2666 | AP30: =AL30-AN30-AO30 -> -9634.4553
A31: 27 | B31: 赣J03535D | C31: 刘炳宏 | D31: 杨发明 | E31: 广西-玉溪 | F31: 桂LB917挂 | G31: 重型半挂牵引车 | H31: =COUNTIFS(磅单!E:E,B31) -> 16 | I31: =SUMIFS(磅单!L:L,磅单!E:E,B31) -> 649.14 | J31: =SUMIFS(磅单!O:O,磅单!E:E,B31) -> 41386.44 | K31: =SUMIFS(月汇总!Y:Y,月汇总!B:B,B31) -> 240 | L31: =SUMIFS(月汇总!I:I,月汇总!B:B,B31,月汇总!C:C,F31) -> 0 | M31: =SUMIFS(月汇总!J:J,月汇总!B:B,B31,月汇总!C:C,F31) -> 12909.952 | N31: =M31/J31 -> 0.31193676 | O31: =M31/H31 -> 806.872 | P31: =SUMIFS(月汇总!R:R,月汇总!B:B,B31)+SUMIFS(月汇总!S:S,月汇总!B:B,B31) -> 10000 | Q31: =P31/J31 -> 0.24162503 | R31: =SUMIFS(月汇总!Q:Q,月汇总!B:B,B31) -> 1405 | S31: =R31/J31 -> 0.033948317 | T31: =SUMIFS(月汇总!N:N,月汇总!B:B,B31) -> 220.88197 | V31: =SUMIFS(月汇总!X:X,月汇总!B:B,B31) -> 0 | X31: =SUMIFS(月汇总!U:U,月汇总!B:B,B31) -> 386 | Y31: =X31/J31 -> 0.0093267263 | Z31: =SUMIFS(月汇总!O:O,月汇总!B:B,B31) -> 8830 | AA31: =Z31/J31 -> 0.21335491 | AB31: =SUMIFS(月汇总!T:T,月汇总!B:B,B31) -> 220 | AC31: =AB31/J31 -> 0.0053157508 | AD31: =SUMIFS(月汇总!Z:Z,月汇总!B:B,B31) -> 2897.0508 | AE31: =AD31/J31 -> 0.07 | AF31: =SUMIFS(月汇总!AC:AC,月汇总!B:B,B31) -> 790.16393 | AG31: =AF31/J31 -> 0.019092339 | AH31: =SUMIFS(月汇总!V:V,月汇总!B:B,B31) -> 397.39246 | AI31: =AH31/J31 -> 0.0096019967 | AJ31: =M31+P31+R31+T31+V31+X31+Z31+AB31+AD31+AF31+AH31 -> 38056.441 | AK31: =SUMIFS(月汇总!AA:AA,月汇总!B:B,B31) -> 10600 | AL31: =J31-K31-L31-AJ31-AK31 -> -7510.0012 | AM31: =AL31/J31 -> -0.18146043 | AN31: =SUMIFS(月汇总!AB:AB,月汇总!B:B,B31) -> 3800 | AO31: =SUMIFS(月汇总!W:W,月汇总!B:B,B31) -> 2666 | AP31: =AL31-AN31-AO31 -> -13976.001
A32: 28 | B32: 赣J09206D | C32: 杨仁华 | D32: 杨发明 | E32: 广西-玉溪 | F32: 桂L9026挂 | G32: 重型半挂牵引车 | H32: =COUNTIFS(磅单!E:E,B32) -> 15 | I32: =SUMIFS(磅单!L:L,磅单!E:E,B32) -> 621.41 | J32: =SUMIFS(磅单!O:O,磅单!E:E,B32) -> 37840.85 | K32: =SUMIFS(月汇总!Y:Y,月汇总!B:B,B32) -> 225 | L32: =SUMIFS(月汇总!I:I,月汇总!B:B,B32,月汇总!C:C,F32) -> 0 | M32: =SUMIFS(月汇总!J:J,月汇总!B:B,B32,月汇总!C:C,F32) -> 13910.791 | N32: =M32/J32 -> 0.36761307 | O32: =M32/H32 -> 927.38607 | P32: =SUMIFS(月汇总!R:R,月汇总!B:B,B32)+SUMIFS(月汇总!S:S,月汇总!B:B,B32) -> 9980 | Q32: =P32/J32 -> 0.26373615 | R32: =SUMIFS(月汇总!Q:Q,月汇总!B:B,B32) -> 2260 | S32: =R32/J32 -> 0.059723817 | T32: =SUMIFS(月汇总!N:N,月汇总!B:B,B32) -> 220.88197 | V32: =SUMIFS(月汇总!X:X,月汇总!B:B,B32) -> 0 | W32: =V32/J32 -> 0 | X32: =SUMIFS(月汇总!U:U,月汇总!B:B,B32) -> 412 | Y32: =X32/J32 -> 0.010887705 | Z32: =SUMIFS(月汇总!O:O,月汇总!B:B,B32) -> 900 | AA32: =Z32/J32 -> 0.023783821 | AB32: =SUMIFS(月汇总!T:T,月汇总!B:B,B32) -> 400 | AC32: =AB32/J32 -> 0.010570587 | AD32: =SUMIFS(月汇总!Z:Z,月汇总!B:B,B32) -> 2648.8595 | AE32: =AD32/J32 -> 0.07 | AF32: =SUMIFS(月汇总!AC:AC,月汇总!B:B,B32) -> 790.16393 | AG32: =AF32/J32 -> 0.020881242 | AH32: =SUMIFS(月汇总!V:V,月汇总!B:B,B32) -> 397.39246 | AI32: =AH32/J32 -> 0.010501679 | AJ32: =M32+P32+R32+T32+V32+X32+Z32+AB32+AD32+AF32+AH32 -> 31920.089 | AK32: =SUMIFS(月汇总!AA:AA,月汇总!B:B,B32) -> 10600 | AL32: =J32-K32-L32-AJ32-AK32 -> -4904.2389 | AM32: =AL32/J32 -> -0.12960171 | AN32: =SUMIFS(月汇总!AB:AB,月汇总!B:B,B32) -> 3800 | AO32: =SUMIFS(月汇总!W:W,月汇总!B:B,B32) -> 2666 | AP32: =AL32-AN32-AO32 -> -11370.239
A33: 29 | B33: 粤B32450D | C33: 潘加松 | D33: 杨发明 | E33: 广西-玉溪 | F33: 桂LB675挂 | G33: 重型半挂牵引车 | H33: =COUNTIFS(磅单!E:E,B33) -> 18 | I33: =SUMIFS(磅单!L:L,磅单!E:E,B33) -> 746.48 | J33: =SUMIFS(磅单!O:O,磅单!E:E,B33) -> 47601.34 | K33: =SUMIFS(月汇总!Y:Y,月汇总!B:B,B33) -> 270 | L33: =SUMIFS(月汇总!I:I,月汇总!B:B,B33,月汇总!C:C,F35) -> 0 | M33: =SUMIFS(月汇总!J:J,月汇总!B:B,B33,月汇总!C:C,F33) -> 14021.364 | N33: =M33/J33 -> 0.29455818 | O33: =M33/H33 -> 778.96467 | P33: =SUMIFS(月汇总!R:R,月汇总!B:B,B33)+SUMIFS(月汇总!S:S,月汇总!B:B,B33) -> 11200 | Q33: =P33/J33 -> 0.23528749 | R33: =SUMIFS(月汇总!Q:Q,月汇总!B:B,B33) -> 352 | S33: =R33/J33 -> 0.0073947498 | T33: =SUMIFS(月汇总!N:N,月汇总!B:B,B33) -> 220.88197 | V33: =SUMIFS(月汇总!X:X,月汇总!B:B,B33) -> 3000 | W33: =V33/J33 -> 0.063023436 | X33: =SUMIFS(月汇总!U:U,月汇总!B:B,B33) -> 535 | Y33: =X33/J33 -> 0.011239179 | Z33: =SUMIFS(月汇总!O:O,月汇总!B:B,B33) -> 0 | AA33: =Z33/J33 -> 0 | AB33: =SUMIFS(月汇总!T:T,月汇总!B:B,B33) -> 200 | AC33: =AB33/J33 -> 0.0042015624 | AD33: =SUMIFS(月汇总!Z:Z,月汇总!B:B,B33) -> 3332.0938 | AE33: =AD33/J33 -> 0.07 | AF33: =SUMIFS(月汇总!AC:AC,月汇总!B:B,B33) -> 790.16393 | AG33: =AF33/J33 -> 0.016599615 | AH33: =SUMIFS(月汇总!V:V,月汇总!B:B,B33) -> 397.39246 | AI33: =AH33/J33 -> 0.0083483461 | AJ33: =M33+P33+R33+T33+V33+X33+Z33+AB33+AD33+AF33+AH33 -> 34048.896 | AK33: =SUMIFS(月汇总!AA:AA,月汇总!B:B,B33) -> 10600 | AL33: =J33-K33-L33-AJ33-AK33 -> 2682.4437 | AM33: =AL33/J33 -> 0.056352273 | AN33: =SUMIFS(月汇总!AB:AB,月汇总!B:B,B33) -> 3800 | AO33: =SUMIFS(月汇总!W:W,月汇总!B:B,B33) -> 2666 | AP33: =AL33-AN33-AO33 -> -3783.5563
A34: 30 | B34: 粤B95976D | C34: 侯开雄 | D34: 杨发明 | E34: 广西-玉溪 | F34: 桂LB629挂 | G34: 重型半挂牵引车 | H34: =COUNTIFS(磅单!E:E,B34) -> 17 | I34: =SUMIFS(磅单!L:L,磅单!E:E,B34) -> 707.89 | J34: =SUMIFS(磅单!O:O,磅单!E:E,B34) -> 45141.65 | K34: =SUMIFS(月汇总!Y:Y,月汇总!B:B,B34) -> 255 | L34: =SUMIFS(月汇总!I:I,月汇总!B:B,B34,月汇总!C:C,F36) -> 0 | M34: =SUMIFS(月汇总!J:J,月汇总!B:B,B34,月汇总!C:C,F34) -> 14959.372 | N34: =M34/J34 -> 0.33138736 | O34: =M34/H34 -> 879.96306 | P34: =SUMIFS(月汇总!R:R,月汇总!B:B,B34)+SUMIFS(月汇总!S:S,月汇总!B:B,B34) -> 10600 | Q34: =P34/J34 -> 0.23481641 | R34: =SUMIFS(月汇总!Q:Q,月汇总!B:B,B34) -> 17300 | S34: =R34/J34 -> 0.3832381 | T34: =SUMIFS(月汇总!N:N,月汇总!B:B,B34) -> 220.88197 | V34: =SUMIFS(月汇总!X:X,月汇总!B:B,B34) -> 3000 | W34: =V34/J34 -> 0.066457473 | X34: =SUMIFS(月汇总!U:U,月汇总!B:B,B34) -> 2989 | Y34: =X34/J34 -> 0.066213796 | Z34: =SUMIFS(月汇总!O:O,月汇总!B:B,B34) -> 0 | AA34: =Z34/J34 -> 0 | AB34: =SUMIFS(月汇总!T:T,月汇总!B:B,B34) -> 0 | AC34: =AB34/J34 -> 0 | AD34: =SUMIFS(月汇总!Z:Z,月汇总!B:B,B34) -> 3159.9155 | AE34: =AD34/J34 -> 0.07 | AF34: =SUMIFS(月汇总!AC:AC,月汇总!B:B,B34) -> 790.16393 | AG34: =AF34/J34 -> 0.0175041 | AH34: =SUMIFS(月汇总!V:V,月汇总!B:B,B34) -> 397.39246 | AI34: =AH34/J34 -> 0.0088032329 | AJ34: =M34+P34+R34+T34+V34+X34+Z34+AB34+AD34+AF34+AH34 -> 53416.726 | AK34: =SUMIFS(月汇总!AA:AA,月汇总!B:B,B34) -> 10600 | AL34: =J34-K34-L34-AJ34-AK34 -> -19130.076 | AM34: =AL34/J34 -> -0.42377884 | AN34: =SUMIFS(月汇总!AB:AB,月汇总!B:B,B34) -> 3800 | AO34: =SUMIFS(月汇总!W:W,月汇总!B:B,B34) -> 2666 | AP34: =AL34-AN34-AO34 -> -25596.076
A35: 31 | B35: 粤B79120D | C35: 周忠银 | D35: 杨发明 | E35: 广西-玉溪 | F35: 桂LD489挂 | G35: 重型半挂牵引车 | H35: =COUNTIFS(磅单!E:E,B35) -> 14 | I35: =SUMIFS(磅单!L:L,磅单!E:E,B35) -> 608.25 | J35: =SUMIFS(磅单!O:O,磅单!E:E,B35) -> 37988.71 | K35: =SUMIFS(月汇总!Y:Y,月汇总!B:B,B35) -> 210 | L35: =SUMIFS(月汇总!I:I,月汇总!B:B,B35,月汇总!C:C,F37) -> 0 | M35: =SUMIFS(月汇总!J:J,月汇总!B:B,B35,月汇总!C:C,F35) -> 13854.188 | N35: =M35/J35 -> 0.36469224 | O35: =M35/H35 -> 989.58483 | P35: =SUMIFS(月汇总!R:R,月汇总!B:B,B35)+SUMIFS(月汇总!S:S,月汇总!B:B,B35) -> 10000 | Q35: =P35/J35 -> 0.2632361 | R35: =SUMIFS(月汇总!Q:Q,月汇总!B:B,B35) -> 230 | S35: =R35/J35 -> 0.0060544304 | T35: =SUMIFS(月汇总!N:N,月汇总!B:B,B35) -> 220.88197 | V35: =SUMIFS(月汇总!X:X,月汇总!B:B,B35) -> 3000 | W35: =V35/J35 -> 0.078970831 | X35: =SUMIFS(月汇总!U:U,月汇总!B:B,B35) -> 466 | Y35: =X35/J35 -> 0.012266802 | Z35: =SUMIFS(月汇总!O:O,月汇总!B:B,B35) -> 0 | AA35: =Z35/J35 -> 0 | AB35: =SUMIFS(月汇总!T:T,月汇总!B:B,B35) -> 200 | AC35: =AB35/J35 -> 0.0052647221 | AD35: =SUMIFS(月汇总!Z:Z,月汇总!B:B,B35) -> 2659.2097 | AE35: =AD35/J35 -> 0.07 | AF35: =SUMIFS(月汇总!AC:AC,月汇总!B:B,B35) -> 790.16393 | AG35: =AF35/J35 -> 0.020799968 | AH35: =SUMIFS(月汇总!V:V,月汇总!B:B,B35) -> 397.39246 | AI35: =AH35/J35 -> 0.010460804 | AJ35: =M35+P35+R35+T35+V35+X35+Z35+AB35+AD35+AF35+AH35 -> 31817.836 | AK35: =SUMIFS(月汇总!AA:AA,月汇总!B:B,B35) -> 10600 | AL35: =J35-K35-L35-AJ35-AK35 -> -4639.1257 | AM35: =AL35/J35 -> -0.12211854 | AN35: =SUMIFS(月汇总!AB:AB,月汇总!B:B,B35) -> 0 | AO35: =SUMIFS(月汇总!W:W,月汇总!B:B,B35) -> 2666 | AP35: =AL35-AN35-AO35 -> -7305.1257
A36: 32 | B36: 粤B43551D | C36: 罗吴华 | D36: 杨发明 | E36: 广西-玉溪 | F36: 桂LC523挂 | G36: 重型半挂牵引车 | H36: =COUNTIFS(磅单!E:E,B36) -> 18 | I36: =SUMIFS(磅单!L:L,磅单!E:E,B36) -> 769.44 | J36: =SUMIFS(磅单!O:O,磅单!E:E,B36) -> 49469.5 | K36: =SUMIFS(月汇总!Y:Y,月汇总!B:B,B36) -> 270 | L36: =SUMIFS(月汇总!I:I,月汇总!B:B,B36,月汇总!C:C,F38) -> 0 | M36: =SUMIFS(月汇总!J:J,月汇总!B:B,B36,月汇总!C:C,F36) -> 19178.568 | N36: =M36/J36 -> 0.3876847 | O36: =M36/H36 -> 1065.476 | P36: =SUMIFS(月汇总!R:R,月汇总!B:B,B36)+SUMIFS(月汇总!S:S,月汇总!B:B,B36) -> 11200 | Q36: =P36/J36 -> 0.22640213 | R36: =SUMIFS(月汇总!Q:Q,月汇总!B:B,B36) -> 100 | S36: =R36/J36 -> 0.0020214476 | T36: =SUMIFS(月汇总!N:N,月汇总!B:B,B36) -> 220.88197 | V36: =SUMIFS(月汇总!X:X,月汇总!B:B,B36) -> 3000 | W36: =V36/J36 -> 0.060643427 | X36: =SUMIFS(月汇总!U:U,月汇总!B:B,B36) -> 424 | Y36: =X36/J36 -> 0.0085709376 | Z36: =SUMIFS(月汇总!O:O,月汇总!B:B,B36) -> 0 | AA36: =Z36/J36 -> 0 | AB36: =SUMIFS(月汇总!T:T,月汇总!B:B,B36) -> 220 | AC36: =AB36/J36 -> 0.0044471846 | AD36: =SUMIFS(月汇总!Z:Z,月汇总!B:B,B36) -> 3462.865 | AE36: =AD36/J36 -> 0.07 | AF36: =SUMIFS(月汇总!AC:AC,月汇总!B:B,B36) -> 790.16393 | AG36: =AF36/J36 -> 0.01597275 | AH36: =SUMIFS(月汇总!V:V,月汇总!B:B,B36) -> 397.39246 | AI36: =AH36/J36 -> 0.0080330802 | AJ36: =M36+P36+R36+T36+V36+X36+Z36+AB36+AD36+AF36+AH36 -> 38993.872 | AK36: =SUMIFS(月汇总!AA:AA,月汇总!B:B,B36) -> 10600 | AL36: =J36-K36-L36-AJ36-AK36 -> -394.37162 | AM36: =AL36/J36 -> -0.0079720155 | AN36: =SUMIFS(月汇总!AB:AB,月汇总!B:B,B36) -> 0 | AO36: =SUMIFS(月汇总!W:W,月汇总!B:B,B36) -> 2666 | AP36: =AL36-AN36-AO36 -> -3060.3716
A37: 33 | B37: 粤B98485D | C37: 覃胜猛 | D37: 陈金杰 | E37: 广西-玉溪 | F37: 桂L4036挂 | G37: 重型半挂牵引车 | H37: =COUNTIFS(磅单!E:E,B37) -> 17 | I37: =SUMIFS(磅单!L:L,磅单!E:E,B37) -> 740.58 | J37: =SUMIFS(磅单!O:O,磅单!E:E,B37) -> 48038.96 | K37: =SUMIFS(月汇总!Y:Y,月汇总!B:B,B37) -> 255 | L37: =SUMIFS(月汇总!I:I,月汇总!B:B,B37,月汇总!C:C,F39) -> 0 | M37: =SUMIFS(月汇总!J:J,月汇总!B:B,B37,月汇总!C:C,F37) -> 17792.421 | N37: =M37/J37 -> 0.37037482 | O37: =M37/H37 -> 1046.613 | P37: =SUMIFS(月汇总!R:R,月汇总!B:B,B37)+SUMIFS(月汇总!S:S,月汇总!B:B,B37) -> 10600 | Q37: =P37/J37 -> 0.22065424 | R37: =SUMIFS(月汇总!Q:Q,月汇总!B:B,B37) -> 50 | S37: =R37/J37 -> 0.0010408219 | T37: =SUMIFS(月汇总!N:N,月汇总!B:B,B37) -> 220.88197 | V37: =SUMIFS(月汇总!X:X,月汇总!B:B,B37) -> 3000 | W37: =V37/J37 -> 0.062449312 | X37: =SUMIFS(月汇总!U:U,月汇总!B:B,B37) -> 410 | Y37: =X37/J37 -> 0.0085347393 | Z37: =SUMIFS(月汇总!O:O,月汇总!B:B,B37) -> 0 | AA37: =Z37/J37 -> 0 | AB37: =SUMIFS(月汇总!T:T,月汇总!B:B,B37) -> 200 | AC37: =AB37/J37 -> 0.0041632875 | AD37: =SUMIFS(月汇总!Z:Z,月汇总!B:B,B37) -> 3362.7272 | AE37: =AD37/J37 -> 0.07 | AF37: =SUMIFS(月汇总!AC:AC,月汇总!B:B,B37) -> 790.16393 | AG37: =AF37/J37 -> 0.016448398 | AH37: =SUMIFS(月汇总!V:V,月汇总!B:B,B37) -> 397.39246 | AI37: =AH37/J37 -> 0.0082722952 | AJ37: =M37+P37+R37+T37+V37+X37+Z37+AB37+AD37+AF37+AH37 -> 36823.587 | AK37: =SUMIFS(月汇总!AA:AA,月汇总!B:B,B37) -> 10600 | AL37: =J37-K37-L37-AJ37-AK37 -> 360.37313 | AM37: =AL37/J37 -> 0.0075016846 | AN37: =SUMIFS(月汇总!AB:AB,月汇总!B:B,B37) -> 0 | AO37: =SUMIFS(月汇总!W:W,月汇总!B:B,B37) -> 2666 | AP37: =AL37-AN37-AO37 -> -2305.6269
A38: 34 | B38: 粤B93085D | C38: 盘靖 | D38: 袁俊杰 | E38: 广西-玉溪 | F38: 桂L13C55挂 | G38: 重型半挂牵引车 | H38: =COUNTIFS(磅单!E:E,B38) -> 9 | I38: =SUMIFS(磅单!L:L,磅单!E:E,B38) -> 393.24 | J38: =SUMIFS(磅单!O:O,磅单!E:E,B38) -> 27869.18 | K38: =SUMIFS(月汇总!Y:Y,月汇总!B:B,B38) -> 135 | L38: =SUMIFS(月汇总!I:I,月汇总!B:B,B38,月汇总!C:C,F40) -> 0 | M38: =SUMIFS(月汇总!J:J,月汇总!B:B,B38,月汇总!C:C,F38) -> 10008.92 | N38: =M38/J38 -> 0.35913938 | O38: =M38/H38 -> 1112.1022 | P38: =SUMIFS(月汇总!R:R,月汇总!B:B,B38)+SUMIFS(月汇总!S:S,月汇总!B:B,B38) -> 6400 | Q38: =P38/J38 -> 0.22964436 | R38: =SUMIFS(月汇总!Q:Q,月汇总!B:B,B38) -> 130 | S38: =R38/J38 -> 0.0046646511 | T38: =SUMIFS(月汇总!N:N,月汇总!B:B,B38) -> 220.88197 | V38: =SUMIFS(月汇总!X:X,月汇总!B:B,B38) -> 3100 | W38: =V38/J38 -> 0.11123399 | X38: =SUMIFS(月汇总!U:U,月汇总!B:B,B38) -> 337 | Y38: =X38/J38 -> 0.012092211 | Z38: =SUMIFS(月汇总!O:O,月汇总!B:B,B38) -> 0 | AA38: =Z38/J38 -> 0 | AB38: =SUMIFS(月汇总!T:T,月汇总!B:B,B38) -> 0 | AC38: =AB38/J38 -> 0 | AD38: =SUMIFS(月汇总!Z:Z,月汇总!B:B,B38) -> 1950.8426 | AE38: =AD38/J38 -> 0.07 | AF38: =SUMIFS(月汇总!AC:AC,月汇总!B:B,B38) -> 790.16393 | AG38: =AF38/J38 -> 0.028352608 | AH38: =SUMIFS(月汇总!V:V,月汇总!B:B,B38) -> 397.39246 | AI38: =AH38/J38 -> 0.014259209 | AJ38: =M38+P38+R38+T38+V38+X38+Z38+AB38+AD38+AF38+AH38 -> 23335.201 | AK38: =SUMIFS(月汇总!AA:AA,月汇总!B:B,B38) -> 10600 | AL38: =J38-K38-L38-AJ38-AK38 -> -6201.0209 | AM38: =AL38/J38 -> -0.2225046 | AN38: =SUMIFS(月汇总!AB:AB,月汇总!B:B,B38) -> 0 | AO38: =SUMIFS(月汇总!W:W,月汇总!B:B,B38) -> 2666 | AP38: =AL38-AN38-AO38 -> -8867.0209
A39: 35 | B39: 粤B85970D | C39: 陆世鹏 | D39: 陈金杰 | E39: 广西-玉溪 | F39: 桂L76464挂 | G39: 重型半挂牵引车 | H39: =COUNTIFS(磅单!E:E,B39) -> 11 | I39: =SUMIFS(磅单!L:L,磅单!E:E,B39) -> 476.11 | J39: =SUMIFS(磅单!O:O,磅单!E:E,B39) -> 31418.83 | K39: =SUMIFS(月汇总!Y:Y,月汇总!B:B,B39) -> 165 | L39: =SUMIFS(月汇总!I:I,月汇总!B:B,B39,月汇总!C:C,F41) -> 0 | M39: =SUMIFS(月汇总!J:J,月汇总!B:B,B39,月汇总!C:C,F39) -> 12396.287 | N39: =M39/J39 -> 0.39454959 | O39: =M39/H39 -> 1126.9351 | P39: =SUMIFS(月汇总!R:R,月汇总!B:B,B39)+SUMIFS(月汇总!S:S,月汇总!B:B,B39) -> 7400 | Q39: =P39/J39 -> 0.23552755 | R39: =SUMIFS(月汇总!Q:Q,月汇总!B:B,B39) -> 90 | S39: =R39/J39 -> 0.0028645242 | T39: =SUMIFS(月汇总!N:N,月汇总!B:B,B39) -> 220.88197 | V39: =SUMIFS(月汇总!X:X,月汇总!B:B,B39) -> 3100 | W39: =V39/J39 -> 0.098666946 | X39: =SUMIFS(月汇总!U:U,月汇总!B:B,B39) -> 328 | Y39: =X39/J39 -> 0.010439599 | Z39: =SUMIFS(月汇总!O:O,月汇总!B:B,B39) -> 0 | AA39: =Z39/J39 -> 0 | AB39: =SUMIFS(月汇总!T:T,月汇总!B:B,B39) -> 200 | AC39: =AB39/J39 -> 0.0063656094 | AD39: =SUMIFS(月汇总!Z:Z,月汇总!B:B,B39) -> 2199.3181 | AE39: =AD39/J39 -> 0.07 | AF39: =SUMIFS(月汇总!AC:AC,月汇总!B:B,B39) -> 790.16393 | AG39: =AF39/J39 -> 0.025149375 | AH39: =SUMIFS(月汇总!V:V,月汇总!B:B,B39) -> 397.39246 | AI39: =AH39/J39 -> 0.012648226 | AJ39: =M39+P39+R39+T39+V39+X39+Z39+AB39+AD39+AF39+AH39 -> 27122.043 | AK39: =SUMIFS(月汇总!AA:AA,月汇总!B:B,B39) -> 10600 | AL39: =J39-K39-L39-AJ39-AK39 -> -6468.2131 | AM39: =AL39/J39 -> -0.20587059 | AN39: =SUMIFS(月汇总!AB:AB,月汇总!B:B,B39) -> 0 | AO39: =SUMIFS(月汇总!W:W,月汇总!B:B,B39) -> 2666 | AP39: =AL39-AN39-AO39 -> -9134.2131
A40: 36 | B40: 粤B78432D | C40: 张俊 | D40: 陈金杰 | E40: 广西-玉溪 | F40: 桂L6429挂 | G40: 重型半挂牵引车 | H40: =COUNTIFS(磅单!E:E,B40) -> 13 | I40: =SUMIFS(磅单!L:L,磅单!E:E,B40) -> 564.55 | J40: =SUMIFS(磅单!O:O,磅单!E:E,B40) -> 40949.85 | K40: =SUMIFS(月汇总!Y:Y,月汇总!B:B,B40) -> 195 | L40: =SUMIFS(月汇总!I:I,月汇总!B:B,B40,月汇总!C:C,F42) -> 0 | M40: =SUMIFS(月汇总!J:J,月汇总!B:B,B40,月汇总!C:C,F40) -> 13245.676 | N40: =M40/J40 -> 0.3234609 | O40: =M40/H40 -> 1018.8981 | P40: =SUMIFS(月汇总!R:R,月汇总!B:B,B40)+SUMIFS(月汇总!S:S,月汇总!B:B,B40) -> 9200 | Q40: =P40/J40 -> 0.22466505 | R40: =SUMIFS(月汇总!Q:Q,月汇总!B:B,B40) -> 180 | S40: =R40/J40 -> 0.0043956205 | T40: =SUMIFS(月汇总!N:N,月汇总!B:B,B40) -> 220.88197 | V40: =SUMIFS(月汇总!X:X,月汇总!B:B,B40) -> 3200 | W40: =V40/J40 -> 0.078144364 | X40: =SUMIFS(月汇总!U:U,月汇总!B:B,B40) -> 229 | Y40: =X40/J40 -> 0.0055922061 | Z40: =SUMIFS(月汇总!O:O,月汇总!B:B,B40) -> 950 | AA40: =Z40/J40 -> 0.023199108 | AB40: =SUMIFS(月汇总!T:T,月汇总!B:B,B40) -> 200 | AC40: =AB40/J40 -> 0.0048840228 | AD40: =SUMIFS(月汇总!Z:Z,月汇总!B:B,B40) -> 2866.4895 | AE40: =AD40/J40 -> 0.07 | AF40: =SUMIFS(月汇总!AC:AC,月汇总!B:B,B40) -> 790.16393 | AG40: =AF40/J40 -> 0.019295893 | AH40: =SUMIFS(月汇总!V:V,月汇总!B:B,B40) -> 397.39246 | AI40: =AH40/J40 -> 0.0097043691 | AJ40: =M40+P40+R40+T40+V40+X40+Z40+AB40+AD40+AF40+AH40 -> 31479.603 | AK40: =SUMIFS(月汇总!AA:AA,月汇总!B:B,B40) -> 10600 | AL40: =J40-K40-L40-AJ40-AK40 -> -1324.7534 | AM40: =AL40/J40 -> -0.032350628 | AN40: =SUMIFS(月汇总!AB:AB,月汇总!B:B,B40) -> 0 | AO40: =SUMIFS(月汇总!W:W,月汇总!B:B,B40) -> 2666 | AP40: =AL40-AN40-AO40 -> -3990.7534
A41: 37 | B41: 粤B94650D | C41: 赵雄 | D41: 陈金杰 | E41: 广西-玉溪 | F41: 桂LD631挂 | G41: 重型半挂牵引车 | H41: =COUNTIFS(磅单!E:E,B41) -> 12 | I41: =SUMIFS(磅单!L:L,磅单!E:E,B41) -> 511.96 | J41: =SUMIFS(磅单!O:O,磅单!E:E,B41) -> 38347.32 | K41: =SUMIFS(月汇总!Y:Y,月汇总!B:B,B41) -> 180 | L41: =SUMIFS(月汇总!I:I,月汇总!B:B,B41,月汇总!C:C,F43) -> 0 | M41: =SUMIFS(月汇总!J:J,月汇总!B:B,B41,月汇总!C:C,F41) -> 13602.169 | N41: =M41/J41 -> 0.35470978 | O41: =M41/H41 -> 1133.5141 | P41: =SUMIFS(月汇总!R:R,月汇总!B:B,B41)+SUMIFS(月汇总!S:S,月汇总!B:B,B41) -> 8800 | Q41: =P41/J41 -> 0.22948149 | R41: =SUMIFS(月汇总!Q:Q,月汇总!B:B,B41) -> 760 | S41: =R41/J41 -> 0.019818856 | T41: =SUMIFS(月汇总!N:N,月汇总!B:B,B41) -> 220.88197 | V41: =SUMIFS(月汇总!X:X,月汇总!B:B,B41) -> 3200 | W41: =V41/J41 -> 0.083447813 | X41: =SUMIFS(月汇总!U:U,月汇总!B:B,B41) -> 210 | Y41: =X41/J41 -> 0.0054762627 | Z41: =SUMIFS(月汇总!O:O,月汇总!B:B,B41) -> 0 | AA41: =Z41/J41 -> 0 | AB41: =SUMIFS(月汇总!T:T,月汇总!B:B,B41) -> 200 | AC41: =AB41/J41 -> 0.0052154883 | AD41: =SUMIFS(月汇总!Z:Z,月汇总!B:B,B41) -> 2684.3124 | AE41: =AD41/J41 -> 0.07 | AF41: =SUMIFS(月汇总!AC:AC,月汇总!B:B,B41) -> 790.16393 | AG41: =AF41/J41 -> 0.020605454 | AH41: =SUMIFS(月汇总!V:V,月汇总!B:B,B41) -> 397.39246 | AI41: =AH41/J41 -> 0.010362979 | AJ41: =M41+P41+R41+T41+V41+X41+Z41+AB41+AD41+AF41+AH41 -> 30864.92 | AK41: =SUMIFS(月汇总!AA:AA,月汇总!B:B,B41) -> 10600 | AL41: =J41-K41-L41-AJ41-AK41 -> -3297.6001 | AM41: =AL41/J41 -> -0.085992973 | AN41: =SUMIFS(月汇总!AB:AB,月汇总!B:B,B41) -> 0 | AO41: =SUMIFS(月汇总!W:W,月汇总!B:B,B41) -> 2666 | AP41: =AL41-AN41-AO41 -> -5963.6001
A42: 38 | B42: 粤B47340D | C42: 曾龙龙 | D42: 陈金杰 | E42: 广西-玉溪 | F42: 桂L5748挂 | G42: 重型半挂牵引车 | H42: =COUNTIFS(磅单!E:E,B42) -> 11 | I42: =SUMIFS(磅单!L:L,磅单!E:E,B42) -> 471.26 | J42: =SUMIFS(磅单!O:O,磅单!E:E,B42) -> 34804.6 | K42: =SUMIFS(月汇总!Y:Y,月汇总!B:B,B42) -> 165 | L42: =SUMIFS(月汇总!I:I,月汇总!B:B,B42,月汇总!C:C,F44) -> 0 | M42: =SUMIFS(月汇总!J:J,月汇总!B:B,B42,月汇总!C:C,F42) -> 12537.759 | N42: =M42/J42 -> 0.3602328 | O42: =M42/H42 -> 1139.7962 | P42: =SUMIFS(月汇总!R:R,月汇总!B:B,B42)+SUMIFS(月汇总!S:S,月汇总!B:B,B42) -> 8000 | Q42: =P42/J42 -> 0.22985467 | R42: =SUMIFS(月汇总!Q:Q,月汇总!B:B,B42) -> 180 | S42: =R42/J42 -> 0.0051717302 | T42: =SUMIFS(月汇总!N:N,月汇总!B:B,B42) -> 220.88197 | V42: =SUMIFS(月汇总!X:X,月汇总!B:B,B42) -> 3200 | W42: =V42/J42 -> 0.09194187 | X42: =SUMIFS(月汇总!U:U,月汇总!B:B,B42) -> 207 | Y42: =X42/J42 -> 0.0059474897 | Z42: =SUMIFS(月汇总!O:O,月汇总!B:B,B42) -> 0 | AA42: =Z42/J42 -> 0 | AB42: =SUMIFS(月汇总!T:T,月汇总!B:B,B42) -> 220 | AC42: =AB42/J42 -> 0.0063210035 | AD42: =SUMIFS(月汇总!Z:Z,月汇总!B:B,B42) -> 2436.322 | AE42: =AD42/J42 -> 0.07 | AF42: =SUMIFS(月汇总!AC:AC,月汇总!B:B,B42) -> 790.16393 | AG42: =AF42/J42 -> 0.022702859 | AH42: =SUMIFS(月汇总!V:V,月汇总!B:B,B42) -> 397.39246 | AI42: =AH42/J42 -> 0.011417814 | AJ42: =M42+P42+R42+T42+V42+X42+Z42+AB42+AD42+AF42+AH42 -> 28189.519 | AK42: =SUMIFS(月汇总!AA:AA,月汇总!B:B,B42) -> 10600 | AL42: =J42-K42-L42-AJ42-AK42 -> -4149.9189 | AM42: =AL42/J42 -> -0.11923478 | AN42: =SUMIFS(月汇总!AB:AB,月汇总!B:B,B42) -> 0 | AO42: =SUMIFS(月汇总!W:W,月汇总!B:B,B42) -> 2666 | AP42: =AL42-AN42-AO42 -> -6815.9189
A43: 39 | B43: 粤B99322D | C43: 李昆 | D43: 陈金杰 | E43: 广西-玉溪 | F43: 桂L6249挂 | G43: 重型半挂牵引车 | H43: =COUNTIFS(磅单!E:E,B43) -> 11 | I43: =SUMIFS(磅单!L:L,磅单!E:E,B43) -> 466.22 | J43: =SUMIFS(磅单!O:O,磅单!E:E,B43) -> 34415.52 | K43: =SUMIFS(月汇总!Y:Y,月汇总!B:B,B43) -> 165 | L43: =SUMIFS(月汇总!I:I,月汇总!B:B,B43,月汇总!C:C,F45) -> 0 | M43: =SUMIFS(月汇总!J:J,月汇总!B:B,B43,月汇总!C:C,F43) -> 12805.259 | N43: =M43/J43 -> 0.37207802 | O43: =M43/H43 -> 1164.1144 | P43: =SUMIFS(月汇总!R:R,月汇总!B:B,B43)+SUMIFS(月汇总!S:S,月汇总!B:B,B43) -> 8000 | Q43: =P43/J43 -> 0.23245327 | R43: =SUMIFS(月汇总!Q:Q,月汇总!B:B,B43) -> 70 | S43: =R43/J43 -> 0.0020339661 | T43: =SUMIFS(月汇总!N:N,月汇总!B:B,B43) -> 220.88197 | V43: =SUMIFS(月汇总!X:X,月汇总!B:B,B43) -> 3200 | W43: =V43/J43 -> 0.092981306 | X43: =SUMIFS(月汇总!U:U,月汇总!B:B,B43) -> 197 | Y43: =X43/J43 -> 0.0057241617 | Z43: =SUMIFS(月汇总!O:O,月汇总!B:B,B43) -> 0 | AA43: =Z43/J43 -> 0 | AB43: =SUMIFS(月汇总!T:T,月汇总!B:B,B43) -> 0 | AC43: =AB43/J43 -> 0 | AD43: =SUMIFS(月汇总!Z:Z,月汇总!B:B,B43) -> 2409.0864 | AE43: =AD43/J43 -> 0.07 | AF43: =SUMIFS(月汇总!AC:AC,月汇总!B:B,B43) -> 790.16393 | AG43: =AF43/J43 -> 0.022959523 | AH43: =SUMIFS(月汇总!V:V,月汇总!B:B,B43) -> 397.39246 | AI43: =AH43/J43 -> 0.011546897 | AJ43: =M43+P43+R43+T43+V43+X43+Z43+AB43+AD43+AF43+AH43 -> 28089.783 | AK43: =SUMIFS(月汇总!AA:AA,月汇总!B:B,B43) -> 10600 | AL43: =J43-K43-L43-AJ43-AK43 -> -4439.2633 | AM43: =AL43/J43 -> -0.12899016 | AN43: =SUMIFS(月汇总!AB:AB,月汇总!B:B,B43) -> 0 | AO43: =SUMIFS(月汇总!W:W,月汇总!B:B,B43) -> 2666 | AP43: =AL43-AN43-AO43 -> -7105.2633
A44: 40 | B44: 粤B96406D | C44: 杨光傅 | D44: 陈金杰 | E44: 广西-玉溪 | F44: 桂L8626挂 | G44: 重型半挂牵引车 | H44: =COUNTIFS(磅单!E:E,B44) -> 13 | I44: =SUMIFS(磅单!L:L,磅单!E:E,B44) -> 565.56 | J44: =SUMIFS(磅单!O:O,磅单!E:E,B44) -> 40860.88 | K44: =SUMIFS(月汇总!Y:Y,月汇总!B:B,B44) -> 195 | L44: =SUMIFS(月汇总!I:I,月汇总!B:B,B44,月汇总!C:C,F46) -> 0 | M44: =SUMIFS(月汇总!J:J,月汇总!B:B,B44,月汇总!C:C,F44) -> 12702.374 | N44: =M44/J44 -> 0.31086882 | O44: =M44/H44 -> 977.10566 | P44: =SUMIFS(月汇总!R:R,月汇总!B:B,B44)+SUMIFS(月汇总!S:S,月汇总!B:B,B44) -> 9000 | Q44: =P44/J44 -> 0.22025957 | R44: =SUMIFS(月汇总!Q:Q,月汇总!B:B,B44) -> 20 | S44: =R44/J44 -> 0.00048946572 | T44: =SUMIFS(月汇总!N:N,月汇总!B:B,B44) -> 220.88197 | V44: =SUMIFS(月汇总!X:X,月汇总!B:B,B44) -> 3200 | W44: =V44/J44 -> 0.078314515 | X44: =SUMIFS(月汇总!U:U,月汇总!B:B,B44) -> 295 | Y44: =X44/J44 -> 0.0072196194 | Z44: =SUMIFS(月汇总!O:O,月汇总!B:B,B44) -> 0 | AA44: =Z44/J44 -> 0 | AB44: =SUMIFS(月汇总!T:T,月汇总!B:B,B44) -> 0 | AC44: =AB44/J44 -> 0 | AD44: =SUMIFS(月汇总!Z:Z,月汇总!B:B,B44) -> 2860.2616 | AE44: =AD44/J44 -> 0.07 | AF44: =SUMIFS(月汇总!AC:AC,月汇总!B:B,B44) -> 790.16393 | AG44: =AF44/J44 -> 0.019337908 | AH44: =SUMIFS(月汇总!V:V,月汇总!B:B,B44) -> 397.39246 | AI44: =AH44/J44 -> 0.0097254993 | AJ44: =M44+P44+R44+T44+V44+X44+Z44+AB44+AD44+AF44+AH44 -> 29486.074 | AK44: =SUMIFS(月汇总!AA:AA,月汇总!B:B,B44) -> 10600 | AL44: =J44-K44-L44-AJ44-AK44 -> 579.80643 | AM44: =AL44/J44 -> 0.014189769 | AN44: =SUMIFS(月汇总!AB:AB,月汇总!B:B,B44) -> 0 | AO44: =SUMIFS(月汇总!W:W,月汇总!B:B,B44) -> 2666 | AP44: =AL44-AN44-AO44 -> -2086.1936
A45: 41 | B45: 粤B95488D | C45: 赵洪凡 | D45: 陈金杰 | E45: 广西-玉溪 | F45: 桂L5939挂 | G45: 重型半挂牵引车 | H45: =COUNTIFS(磅单!E:E,B45) -> 10 | I45: =SUMIFS(磅单!L:L,磅单!E:E,B45) -> 433.28 | J45: =SUMIFS(磅单!O:O,磅单!E:E,B45) -> 30994.56 | K45: =SUMIFS(月汇总!Y:Y,月汇总!B:B,B45) -> 150 | L45: =SUMIFS(月汇总!I:I,月汇总!B:B,B45,月汇总!C:C,F66) -> 0 | M45: =SUMIFS(月汇总!J:J,月汇总!B:B,B45,月汇总!C:C,F45) -> 10634.231 | N45: =M45/J45 -> 0.34309992 | O45: =M45/H45 -> 1063.4231 | P45: =SUMIFS(月汇总!R:R,月汇总!B:B,B45)+SUMIFS(月汇总!S:S,月汇总!B:B,B45) -> 7000 | Q45: =P45/J45 -> 0.22584608 | R45: =SUMIFS(月汇总!Q:Q,月汇总!B:B,B45) -> 260 | S45: =R45/J45 -> 0.0083885688 | T45: =SUMIFS(月汇总!N:N,月汇总!B:B,B45) -> 220.88197 | V45: =SUMIFS(月汇总!X:X,月汇总!B:B,B45) -> 3200 | W45: =V45/J45 -> 0.10324392 | X45: =SUMIFS(月汇总!U:U,月汇总!B:B,B45) -> 175 | Y45: =X45/J45 -> 0.0056461521 | Z45: =SUMIFS(月汇总!O:O,月汇总!B:B,B45) -> 950 | AA45: =Z45/J45 -> 0.03065054 | AB45: =SUMIFS(月汇总!T:T,月汇总!B:B,B45) -> 0 | AC45: =AB45/J45 -> 0 | AD45: =SUMIFS(月汇总!Z:Z,月汇总!B:B,B45) -> 2169.6192 | AE45: =AD45/J45 -> 0.07 | AF45: =SUMIFS(月汇总!AC:AC,月汇总!B:B,B45) -> 790.16393 | AG45: =AF45/J45 -> 0.025493633 | AH45: =SUMIFS(月汇总!V:V,月汇总!B:B,B45) -> 397.39246 | AI45: =AH45/J45 -> 0.012821362 | AJ45: =M45+P45+R45+T45+V45+X45+Z45+AB45+AD45+AF45+AH45 -> 25797.288 | AK45: =SUMIFS(月汇总!AA:AA,月汇总!B:B,B45) -> 0 | AL45: =J45-K45-L45-AJ45-AK45 -> 5047.2715 | AM45: =AL45/J45 -> 0.16284379 | AN45: =SUMIFS(月汇总!AB:AB,月汇总!B:B,B45) -> 0 | AO45: =SUMIFS(月汇总!W:W,月汇总!B:B,B45) -> 2666 | AP45: =AL45-AN45-AO45 -> 2381.2715
A46: 42 | B46: 云F03990D | C46: 赵大云 | D46: 杨发明 | E46: 广西-玉溪 | F46: 桂LB629挂 | G46: 重型半挂牵引车 | H46: =COUNTIFS(磅单!E:E,B46) -> 7 | I46: =SUMIFS(磅单!L:L,磅单!E:E,B46) -> 288.78 | J46: =SUMIFS(磅单!O:O,磅单!E:E,B46) -> 16681.4 | K46: =SUMIFS(月汇总!Y:Y,月汇总!B:B,B46) -> 105 | L46: =SUMIFS(月汇总!I:I,月汇总!B:B,B46,月汇总!C:C,F67) -> 0 | M46: =SUMIFS(月汇总!J:J,月汇总!B:B,B46) -> 5341.5002 | N46: =M46/J46 -> 0.32020695 | O46: =M46/H46 -> 763.07146 | P46: =SUMIFS(月汇总!R:R,月汇总!B:B,B46)+SUMIFS(月汇总!S:S,月汇总!B:B,B46) -> 4200 | Q46: =P46/J46 -> 0.25177743 | R46: =SUMIFS(月汇总!Q:Q,月汇总!B:B,B46) -> 60 | S46: =R46/J46 -> 0.0035968204 | T46: =SUMIFS(月汇总!N:N,月汇总!B:B,B46) -> 220.88197 | V46: =SUMIFS(月汇总!X:X,月汇总!B:B,B46) -> 0 | W46: =V46/J46 -> 0 | X46: =SUMIFS(月汇总!U:U,月汇总!B:B,B46) -> 855.4 | Y46: =X46/J46 -> 0.05127867 | Z46: =SUMIFS(月汇总!O:O,月汇总!B:B,B46) -> 0 | AA46: =Z46/J46 -> 0 | AB46: =SUMIFS(月汇总!T:T,月汇总!B:B,B46) -> 0 | AC46: =AB46/J46 -> 0 | AD46: =SUMIFS(月汇总!Z:Z,月汇总!B:B,B46) -> 1167.698 | AE46: =AD46/J46 -> 0.07 | AF46: =SUMIFS(月汇总!AC:AC,月汇总!B:B,B46) -> 790.16393 | AG46: =AF46/J46 -> 0.047367963 | AH46: =SUMIFS(月汇总!V:V,月汇总!B:B,B46) -> 397.39246 | AI46: =AH46/J46 -> 0.023822488 | AJ46: =M46+P46+R46+T46+V46+X46+Z46+AB46+AD46+AF46+AH46 -> 13033.037 | AK46: =SUMIFS(月汇总!AA:AA,月汇总!B:B,B46) -> 0 | AL46: =J46-K46-L46-AJ46-AK46 -> 3543.3634 | AM46: =AL46/J46 -> 0.21241403 | AN46: =SUMIFS(月汇总!AB:AB,月汇总!B:B,B46) -> 2280 | AO46: =SUMIFS(月汇总!W:W,月汇总!B:B,B46) -> 0 | AP46: =AL46-AN46-AO46 -> 1263.3634
A47: 43 | B47: 粤B87855D | C47: 马辉 | D47: 陈金杰 | E47: 广西-玉溪 | F47: 桂LD762挂 | G47: 重型半挂牵引车 | H47: =COUNTIFS(磅单!E:E,B47) -> 10 | I47: =SUMIFS(磅单!L:L,磅单!E:E,B47) -> 427.61 | J47: =SUMIFS(磅单!O:O,磅单!E:E,B47) -> 31830.41 | K47: =SUMIFS(月汇总!Y:Y,月汇总!B:B,B47) -> 150 | L47: =SUMIFS(月汇总!I:I,月汇总!B:B,B47,月汇总!C:C,F68) -> 0 | M47: =SUMIFS(月汇总!J:J,月汇总!B:B,B47,月汇总!C:C,F47) -> 12209.052 | N47: =M47/J47 -> 0.38356566 | O47: =M47/H47 -> 1220.9052 | P47: =SUMIFS(月汇总!R:R,月汇总!B:B,B47)+SUMIFS(月汇总!S:S,月汇总!B:B,B47) -> 7200 | Q47: =P47/J47 -> 0.22619878 | R47: =SUMIFS(月汇总!Q:Q,月汇总!B:B,B47) -> 0 | S47: =R47/J47 -> 0 | T47: =SUMIFS(月汇总!N:N,月汇总!B:B,B47) -> 220.88197 | V47: =SUMIFS(月汇总!X:X,月汇总!B:B,B47) -> 3200 | W47: =V47/J47 -> 0.10053279 | X47: =SUMIFS(月汇总!U:U,月汇总!B:B,B47) -> 194 | Y47: =X47/J47 -> 0.0060948005 | Z47: =SUMIFS(月汇总!O:O,月汇总!B:B,B47) -> 0 | AA47: =Z47/J47 -> 0 | AB47: =SUMIFS(月汇总!T:T,月汇总!B:B,B47) -> 0 | AC47: =AB47/J47 -> 0 | AD47: =SUMIFS(月汇总!Z:Z,月汇总!B:B,B47) -> 2228.1287 | AE47: =AD47/J47 -> 0.07 | AF47: =SUMIFS(月汇总!AC:AC,月汇总!B:B,B47) -> 790.16393 | AG47: =AF47/J47 -> 0.024824183 | AH47: =SUMIFS(月汇总!V:V,月汇总!B:B,B47) -> 397.39246 | AI47: =AH47/J47 -> 0.012484679 | AJ47: =M47+P47+R47+T47+V47+X47+Z47+AB47+AD47+AF47+AH47 -> 26439.619 | AK47: =SUMIFS(月汇总!AA:AA,月汇总!B:B,B47) -> 0 | AL47: =J47-K47-L47-AJ47-AK47 -> 5240.7907 | AM47: =AL47/J47 -> 0.16464729 | AN47: =SUMIFS(月汇总!AB:AB,月汇总!B:B,B47) -> 0 | AO47: =SUMIFS(月汇总!W:W,月汇总!B:B,B47) -> 2666 | AP47: =AL47-AN47-AO47 -> 2574.7907
A48: 44 | B48: 粤B49365D | C48: 兰荣建 | D48: 陈金杰 | E48: 广西-玉溪 | F48: 桂LC671挂 | G48: 重型半挂牵引车 | H48: =COUNTIFS(磅单!E:E,B48) -> 11 | I48: =SUMIFS(磅单!L:L,磅单!E:E,B48) -> 463.5 | J48: =SUMIFS(磅单!O:O,磅单!E:E,B48) -> 34892.06 | K48: =SUMIFS(月汇总!Y:Y,月汇总!B:B,B48) -> 150 | L48: =SUMIFS(月汇总!I:I,月汇总!B:B,B48,月汇总!C:C,F69) -> 0 | M48: =SUMIFS(月汇总!J:J,月汇总!B:B,B48,月汇总!C:C,F48) -> 11158.452 | N48: =M48/J48 -> 0.31979916 | O48: =M48/H48 -> 1014.4047 | P48: =SUMIFS(月汇总!R:R,月汇总!B:B,B48)+SUMIFS(月汇总!S:S,月汇总!B:B,B48) -> 7800 | Q48: =P48/J48 -> 0.22354656 | R48: =SUMIFS(月汇总!Q:Q,月汇总!B:B,B48) -> 60 | S48: =R48/J48 -> 0.0017195889 | T48: =SUMIFS(月汇总!N:N,月汇总!B:B,B48) -> 220.88197 | V48: =SUMIFS(月汇总!X:X,月汇总!B:B,B48) -> 2800 | W48: =V48/J48 -> 0.080247483 | X48: =SUMIFS(月汇总!U:U,月汇总!B:B,B48) -> 173 | Y48: =X48/J48 -> 0.0049581481 | Z48: =SUMIFS(月汇总!O:O,月汇总!B:B,B48) -> 0 | AA48: =Z48/J48 -> 0 | AB48: =SUMIFS(月汇总!T:T,月汇总!B:B,B48) -> 0 | AC48: =AB48/J48 -> 0 | AD48: =SUMIFS(月汇总!Z:Z,月汇总!B:B,B48) -> 2442.4442 | AE48: =AD48/J48 -> 0.07 | AF48: =SUMIFS(月汇总!AC:AC,月汇总!B:B,B48) -> 790.16393 | AG48: =AF48/J48 -> 0.022645953 | AH48: =SUMIFS(月汇总!V:V,月汇总!B:B,B48) -> 397.39246 | AI48: =AH48/J48 -> 0.011389195 | AJ48: =M48+P48+R48+T48+V48+X48+Z48+AB48+AD48+AF48+AH48 -> 25842.334 | AK48: =SUMIFS(月汇总!AA:AA,月汇总!B:B,B48) -> 0 | AL48: =J48-K48-L48-AJ48-AK48 -> 8899.7259 | AM48: =AL48/J48 -> 0.2550645 | AN48: =SUMIFS(月汇总!AB:AB,月汇总!B:B,B48) -> 0 | AO48: =SUMIFS(月汇总!W:W,月汇总!B:B,B48) -> 2666 | AP48: =AL48-AN48-AO48 -> 6233.7259
...

Sheet 6月
A1: 应收汇总表
A2: 序号 | B2: 客户 | C2: 前期应收 | D2: 3月应收 | E2: 3月已收 | F2: 合计未收
A3: 1 | B3: 广西华银铝业有限公司 | C3: 160255.36 | D3: =SUMIFS(磅单!O:O,磅单!D:D,B:B) -> 664162.44 | E3: 300000 | F3: =D3-E3+C3 -> 524417.8
A4: 2 | B4: 广西信发物流有限公司(铝粉) | C4: 70646.72 | D4: =SUMIFS(磅单!O:O,磅单!D:D,B:B) -> 27568.26 | F4: =D4-E4+C4 -> 98214.98
A5: 3 | B5: 云南省煤炭交易（储配）中心有限公司 | C5: 193999.82 | D5: =SUMIFS(磅单!O:O,磅单!D:D,B:B) -> 820260.91 | E5: 224870.3 | F5: =D5-E5+C5 -> 789390.43
A6: 4 | B6: 靖西天桂铝业有限公司 | C6: 127283.62 | D6: =SUMIFS(磅单!O:O,磅单!D:D,B:B) -> 194197.36 | F6: =D6-E6+C6 -> 321480.98
A7: 5 | B7: 广西田东锦鑫化工有限公司 | D7: =SUMIFS(磅单!O:O,磅单!D:D,B:B) -> 413034.24 | F7: =D7-E7+C7 -> 413034.24
A8: 合计 | C8: =SUM(C3:C7)-27315.22 -> 524870.3 | D8: =SUM(D3:D7)-月汇总!Y63-月汇总!Y68-月汇总!I63-月汇总!I68 -> 2107293.2 | E8: =SUM(E3:E7) -> 524870.3 | F8: =C8+D8-E8 -> 2107293.2
A10: 二、应付账款
A11: 应付汇总表
A12: 序号 | B12: 客户 | C12: 前期未付 | D12: 4月应付 | E12: 4月已付 | F12: 合计未付
A13: 1 | B13: 充电费 | C13: -122541.36 | D13: =月汇总!J63+月汇总!J68 -> 707281.99 | E13: =SUMIFS(农行卡!#REF!,农行卡!#REF!,B13)+SUMIFS(微信!#REF!,微信!#REF!,B13)+SUMIFS(骏恒对公户!#REF!,骏恒对公户!#REF!,B13) -> #REF! | F13: =C13+D13-E13 -> #REF!
A14: 2 | B14: 配件费 | C14: 0 | D14: =月汇总!N63+月汇总!N68 -> 13473.8 | E14: =SUMIFS(微信!#REF!,微信!#REF!,B14)+SUMIFS(骏恒对公户!#REF!,骏恒对公户!#REF!,B14)+6300 -> #REF! | F14: =C14+D14-E14 -> #REF!
A15: 3 | B15: 轮胎费 | C15: 780 | D15: =月汇总!O63+月汇总!O68 -> 46150 | E15: =SUMIFS(农行卡!#REF!,农行卡!#REF!,B15)+SUMIFS(微信!#REF!,微信!#REF!,B15)+SUMIFS(骏恒对公户!#REF!,骏恒对公户!#REF!,B15) -> #REF! | F15: =C15+D15-E15 -> #REF!
A16: 4 | B16: 高速费 | C16: 0 | D16: =月汇总!P63 -> 0 | E16: =SUMIFS(农行卡!#REF!,农行卡!#REF!,B16)+SUMIFS(微信!#REF!,微信!#REF!,B16)+SUMIFS(骏恒对公户!#REF!,骏恒对公户!#REF!,B16) -> #REF! | F16: =C16+D16-E16 -> #REF!
A17: 5 | B17: 车队-司机工资 | C17: 380100 | D17: =月汇总!R63+月汇总!S63+月汇总!S68+月汇总!R68 -> 504580 | E17: =SUMIFS(农行卡!#REF!,农行卡!#REF!,B17)+SUMIFS(微信!#REF!,微信!#REF!,B17)+SUMIFS(骏恒对公户!#REF!,骏恒对公户!#REF!,B17) -> #REF! | F17: =C17+D17-E17 -> #REF!
A18: 6 | B18: 维修费 | C18: 37586.08 | D18: =月汇总!Q63+月汇总!Q68 -> 55270 | E18: =SUMIFS(农行卡!#REF!,农行卡!#REF!,B18)+SUMIFS(微信!#REF!,微信!#REF!,B18)+SUMIFS(骏恒对公户!#REF!,骏恒对公户!#REF!,B18) -> #REF! | F18: =C18+D18-E18 -> #REF!
A19: 7 | B19: 车辆费用 | C19: 135 | D19: =月汇总!U63+月汇总!U68 -> 26221.1 | E19: =SUMIFS(农行卡!#REF!,农行卡!#REF!,B19)+SUMIFS(微信!#REF!,微信!#REF!,B19)+SUMIFS(骏恒对公户!#REF!,骏恒对公户!#REF!,B19) -> #REF! | F19: =C19+D19-E19 -> #REF!
A20: 8 | B20: 综合费用 | C20: 12903.072 | D20: =月汇总!V63+月汇总!V68+月汇总!X63+月汇总!X68 -> 125040.94 | E20: =SUMIFS(农行卡!#REF!,农行卡!#REF!,B20)+SUMIFS(微信!#REF!,微信!#REF!,B20)+SUMIFS(骏恒对公户!#REF!,骏恒对公户!#REF!,B20) -> #REF! | F20: =C20+D20-E20 -> #REF!
A21: 9 | B21: 车头利息 | C21: 285858.06 | D21: =月汇总!AA63 -> 424000 | E21: =SUMIFS(农行卡!#REF!,农行卡!#REF!,B21)+SUMIFS(微信!#REF!,微信!#REF!,B21)+SUMIFS(骏恒对公户!#REF!,骏恒对公户!#REF!,B21)+285858.06 -> #REF! | F21: =C21+D21-E21 -> #REF!
A22: 10 | B22: 挂板租金 | C22: 111401.3 | D22: =月汇总!AB63+月汇总!AB68 -> 116280 | E22: =SUMIFS(农行卡!#REF!,农行卡!#REF!,B22)+SUMIFS(微信!#REF!,微信!#REF!,B22)+SUMIFS(骏恒对公户!#REF!,骏恒对公户!#REF!,B22) -> #REF! | F22: =C22+D22-E22 -> #REF!
A23: 11 | B23: 保险 | C23: 71895.997 | D23: =月汇总!W63 -> 157294 | E23: =SUMIFS(农行卡!#REF!,农行卡!#REF!,B23)+SUMIFS(微信!#REF!,微信!#REF!,B23)+SUMIFS(骏恒对公户!#REF!,骏恒对公户!#REF!,B23)+71896 -> #REF! | F23: =C23+D23-E23 -> #REF!
A24: 12 | B24: 管理人员工资 | C24: 28029.099 | D24: =月汇总!AC63+月汇总!AC68 -> 48200 | E24: =SUMIFS(农行卡!#REF!,农行卡!#REF!,B24)+SUMIFS(微信!#REF!,微信!#REF!,B24)+SUMIFS(骏恒对公户!#REF!,骏恒对公户!#REF!,B24) -> #REF! | F24: =C24+D24-E24 -> #REF!
A25: 13 | B25: 车队-罚款 | C25: 0 | D25: =月汇总!T63+月汇总!T68 -> 8290 | E25: =SUMIFS(农行卡!#REF!,农行卡!#REF!,B25)+SUMIFS(微信!#REF!,微信!#REF!,B25)+SUMIFS(骏恒对公户!#REF!,骏恒对公户!#REF!,B25) -> #REF! | F25: =C25+D25-E25 -> #REF!
A26: 14 | B26: 税点费用 | C26: 212217.93 | D26: =月汇总!Z63+月汇总!Z68 -> 148345.62 | E26: =SUMIFS(农行卡!#REF!,农行卡!#REF!,B26)+SUMIFS(微信!#REF!,微信!#REF!,B26)+SUMIFS(骏恒对公户!#REF!,骏恒对公户!#REF!,B26) -> #REF! | F26: =C26+D26-E26 -> #REF!
A27: 合计 | C27: =SUM(C13:C26) -> 1018365.2 | D27: =SUM(D13:D26) -> 2380427.5 | E27: =SUM(E13:E26) -> #REF! | F27: =SUM(F13:F26) -> #REF!
C28: 应收-应付 | D28: =D8-D27 -> -273134.24
C29: 利润 | D29: =月汇总!AD63+月汇总!AD68 -> -273134.24
D30: =D28-D29 -> -1.2223609e-09
A31: 三、其他应收
A32: 序号 | B32: 应收账款 | C32: 前期未收 | D32: 6月应收 | E32: 6月已收 | F32: 未收
A33: 1 | B33: 借款（联合重卡） | C33: 0
A34: 2 | B34: 借款（高彩云） | C34: 0
A35: 3 | B35: 其他应收款-房租押金 | C35: 4000 | F35: =C35+D35-E35 -> 4000
A36: 4 | B36: 其他应收款-代付联合重卡前期费用 | C36: 49830.99 | F36: =C36+D36-E36 -> 49830.99
A37: 5 | B37: 陈庆 | C37: 0 | F37: =C37+D37-E37 -> 0
A38: 6 | B38: 其他应收款-赫荣 | C38: 0 | F38: =C38+D38-E38 -> 0
A39: 7 | B39: 江西同欣达汽车贸易有限公司 | C39: 650000 | E39: 650000 | F39: =C39+D39-E39 -> 0
A40: 8 | B40: 杨发明 | D40: 25000 | F40: =C40+D40-E40 -> 25000
A41: 9 | B41: 赣J03373D配件款 | D41: 2050 | F41: =C41+D41-E41 -> 2050
...

Sheet 月汇总
A1: 2026年玉溪广西6月报汇总表
A2: 序号 | B2: 车牌 | C2: 挂板 | D2: 司机 | E2: 车辆状态 | F2: 趟数 | G2: 卸货吨位 | H2: 含税产值 | I2: 磅差和罚款金额 | J2: 电费 | K2: 电费占比 | L2: 单趟电耗 | M2: 电费税点 | N2: 配件费 | O2: 轮胎费 | P2: 高速费 | Q2: 维修费 | R2: 提成工资 | S2: 补助 | T2: 罚款 | U2: 车辆费用 | V2: 均摊 | W2: 车辆保险 | X2: 前期费用 | Y2: 货物险 | Z2: 税点 | AA2: 贷款 | AB2: 挂板租金/贷款 | AC2: 管理人员工资 | AD2: 利润
